Workbook

Sheet Oct 25
A2: DATE | B2: LINE | C2: SHIP NAME | D2: Catamaran Sail & Snorkel | F2: Champagne Adults Only | H2: Invisible Boat Family | BR2: PAX TOTALS, ANALYSIS and RATES
D3: Sold | E3: Allotment | F3: Sold | G3: Allotment | H3: Sold | I3: Allotment | J3: Sold | K3: Allotment | L3: Sold | M3: Allotment | N3: Sold | O3: Allotment | P3: Sold | Q3: Allotment | R3: Sold | S3: Allotment | T3: Sold | U3: Allotment | V3: Sold | W3: Allotment | X3: Sold | Y3: Allotment | Z3: Sold | AA3: Allotment | AB3: Sold | AC3: Allotment | AD3: Sold | AE3: Allotment | AF3: Sold | AG3: Allotment | AH3: Sold | AI3: Allotment | AJ3: Sold | AK3: Allotment | AL3: Sold | AM3: Allotment | AN3: Sold | AO3: Allotment | AP3: Sold | AQ3: Allotment | AR3: Sold | AS3: Allotment | AT3: Sold | AU3: Allotment | AV3: Sold | AW3: Allotment | AX3: Sold | AY3: Allotment | AZ3: Sold | BA3: Allotment | BB3: Sold | BC3: Allotment | BD3: Sold | BE3: Allotment | BF3: Sold | BG3: Allotment | BH3: Sold | BI3: Allotment | BJ3: Sold | BK3: Allotment | BL3: Sold | BM3: Allotment | BN3: Sold | BO3: Allotment | BP3: Sold | BQ3: Allotment | BR3: Chukka Tours (Sold) | BS3: Alloted Pax | BT3: Pax on Board | BU3: Pax on Tour | BV3: Capture Rate | BW3: Utilization Rate | BX3: Market Share
A4: {{date}} | B4: {{cruise_line}} | C4: {{ship_name}} | D4: {{cat_sold}} | E4: {{cat_allot}} | F4: {{champ_sold}} | G4: {{champ_allot}} | H4: {{inv_sold}} | I4: {{inv_allot}} | BR4: =D4+F4+H4+J4+L4+N4+V4+X4+Z4+AB4+AD4+AF4+AZ4+BB4+BD4+BF4+BH4+AH4+P4+R4+AJ4+BJ4+AL4+AN4+AP4+AR4+AT4+AX4+AV4+BL4+T4+BN4+BP4 -> #VALUE! | BS4: =E4+G4+I4+K4+M4+O4+W4+Y4+AA4+AC4+AE4+AG4+BA4+BC4+BE4+BG4+BI4+AI4+Q4+S4+AK4+BK4+AM4+AO4+AQ4+AS4+AU4+AY4+AW4+BM4+U4+BO4+BQ4 -> #VALUE! | BT4: {{pax_on_board}} | BU4: {{pax_on_tour}} | BV4: =IF(BR4=0, "", BR4/BT4) -> #VALUE! | BW4: =IF(BR4=0, "", BR4/BS4) -> #VALUE! | BX4: =IF(BR4=0, "", BR4/BU4) -> #VALUE!
BR5: =D5+F5+H5+J5+L5+N5+V5+X5+Z5+AB5+AD5+AF5+AZ5+BB5+BD5+BF5+BH5+AH5+P5+R5+AJ5+BJ5+AL5+AN5+AP5+AR5+AT5+AX5+AV5+BL5+T5+BN5+BP5 -> 0 | BS5: =E5+G5+I5+K5+M5+O5+W5+Y5+AA5+AC5+AE5+AG5+BA5+BC5+BE5+BG5+BI5+AI5+Q5+S5+AK5+BK5+AM5+AO5+AQ5+AS5+AU5+AY5+AW5+BM5+U5+BO5+BQ5 -> 0 | BV5: =IF(BR5=0, "", BR5/BT5) | BW5: =IF(BR5=0, "", BR5/BS5) | BX5: =IF(BR5=0, "", BR5/BU5)
BR6: =D6+F6+H6+J6+L6+N6+V6+X6+Z6+AB6+AD6+AF6+AZ6+BB6+BD6+BF6+BH6+AH6+P6+R6+AJ6+BJ6+AL6+AN6+AP6+AR6+AT6+AX6+AV6+BL6+T6+BN6+BP6 -> 0 | BS6: =E6+G6+I6+K6+M6+O6+W6+Y6+AA6+AC6+AE6+AG6+BA6+BC6+BE6+BG6+BI6+AI6+Q6+S6+AK6+BK6+AM6+AO6+AQ6+AS6+AU6+AY6+AW6+BM6+U6+BO6+BQ6 -> 0 | BV6: =IF(BR6=0, "", BR6/BT6) | BW6: =IF(BR6=0, "", BR6/BS6) | BX6: =IF(BR6=0, "", BR6/BU6)
BR7: =D7+F7+H7+J7+L7+N7+V7+X7+Z7+AB7+AD7+AF7+AZ7+BB7+BD7+BF7+BH7+AH7+P7+R7+AJ7+BJ7+AL7+AN7+AP7+AR7+AT7+AX7+AV7+BL7+T7+BN7+BP7 -> 0 | BS7: =E7+G7+I7+K7+M7+O7+W7+Y7+AA7+AC7+AE7+AG7+BA7+BC7+BE7+BG7+BI7+AI7+Q7+S7+AK7+BK7+AM7+AO7+AQ7+AS7+AU7+AY7+AW7+BM7+U7+BO7+BQ7 -> 0 | BV7: =IF(BR7=0, "", BR7/BT7) | BW7: =IF(BR7=0, "", BR7/BS7) | BX7: =IF(BR7=0, "", BR7/BU7)
BR8: =D8+F8+H8+J8+L8+N8+V8+X8+Z8+AB8+AD8+AF8+AZ8+BB8+BD8+BF8+BH8+AH8+P8+R8+AJ8+BJ8+AL8+AN8+AP8+AR8+AT8+AX8+AV8+BL8+T8+BN8+BP8 -> 0 | BS8: =E8+G8+I8+K8+M8+O8+W8+Y8+AA8+AC8+AE8+AG8+BA8+BC8+BE8+BG8+BI8+AI8+Q8+S8+AK8+BK8+AM8+AO8+AQ8+AS8+AU8+AY8+AW8+BM8+U8+BO8+BQ8 -> 0 | BV8: =IF(BR8=0, "", BR8/BT8) | BW8: =IF(BR8=0, "", BR8/BS8) | BX8: =IF(BR8=0, "", BR8/BU8)
BR9: =D9+F9+H9+J9+L9+N9+V9+X9+Z9+AB9+AD9+AF9+AZ9+BB9+BD9+BF9+BH9+AH9+P9+R9+AJ9+BJ9+AL9+AN9+AP9+AR9+AT9+AX9+AV9+BL9+T9+BN9+BP9 -> 0 | BS9: =E9+G9+I9+K9+M9+O9+W9+Y9+AA9+AC9+AE9+AG9+BA9+BC9+BE9+BG9+BI9+AI9+Q9+S9+AK9+BK9+AM9+AO9+AQ9+AS9+AU9+AY9+AW9+BM9+U9+BO9+BQ9 -> 0 | BV9: =IF(BR9=0, "", BR9/BT9) | BW9: =IF(BR9=0, "", BR9/BS9) | BX9: =IF(BR9=0, "", BR9/BU9)
BR10: =D10+F10+H10+J10+L10+N10+V10+X10+Z10+AB10+AD10+AF10+AZ10+BB10+BD10+BF10+BH10+AH10+P10+R10+AJ10+BJ10+AL10+AN10+AP10+AR10+AT10+AX10+AV10+BL10+T10+BN10+BP10 -> 0 | BS10: =E10+G10+I10+K10+M10+O10+W10+Y10+AA10+AC10+AE10+AG10+BA10+BC10+BE10+BG10+BI10+AI10+Q10+S10+AK10+BK10+AM10+AO10+AQ10+AS10+AU10+AY10+AW10+BM10+U10+BO10+BQ10 -> 0 | BV10: =IF(BR10=0, "", BR10/BT10) | BW10: =IF(BR10=0, "", BR10/BS10) | BX10: =IF(BR10=0, "", BR10/BU10)
BR11: =D11+F11+H11+J11+L11+N11+V11+X11+Z11+AB11+AD11+AF11+AZ11+BB11+BD11+BF11+BH11+AH11+P11+R11+AJ11+BJ11+AL11+AN11+AP11+AR11+AT11+AX11+AV11+BL11+T11+BN11+BP11 -> 0 | BS11: =E11+G11+I11+K11+M11+O11+W11+Y11+AA11+AC11+AE11+AG11+BA11+BC11+BE11+BG11+BI11+AI11+Q11+S11+AK11+BK11+AM11+AO11+AQ11+AS11+AU11+AY11+AW11+BM11+U11+BO11+BQ11 -> 0 | BV11: =IF(BR11=0, "", BR11/BT11) | BW11: =IF(BR11=0, "", BR11/BS11) | BX11: =IF(BR11=0, "", BR11/BU11)
BR12: =D12+F12+H12+J12+L12+N12+V12+X12+Z12+AB12+AD12+AF12+AZ12+BB12+BD12+BF12+BH12+AH12+P12+R12+AJ12+BJ12+AL12+AN12+AP12+AR12+AT12+AX12+AV12+BL12+T12+BN12+BP12 -> 0 | BS12: =E12+G12+I12+K12+M12+O12+W12+Y12+AA12+AC12+AE12+AG12+BA12+BC12+BE12+BG12+BI12+AI12+Q12+S12+AK12+BK12+AM12+AO12+AQ12+AS12+AU12+AY12+AW12+BM12+U12+BO12+BQ12 -> 0 | BV12: =IF(BR12=0, "", BR12/BT12) | BW12: =IF(BR12=0, "", BR12/BS12) | BX12: =IF(BR12=0, "", BR12/BU12)
BR13: =D13+F13+H13+J13+L13+N13+V13+X13+Z13+AB13+AD13+AF13+AZ13+BB13+BD13+BF13+BH13+AH13+P13+R13+AJ13+BJ13+AL13+AN13+AP13+AR13+AT13+AX13+AV13+BL13+T13+BN13+BP13 -> 0 | BS13: =E13+G13+I13+K13+M13+O13+W13+Y13+AA13+AC13+AE13+AG13+BA13+BC13+BE13+BG13+BI13+AI13+Q13+S13+AK13+BK13+AM13+AO13+AQ13+AS13+AU13+AY13+AW13+BM13+U13+BO13+BQ13 -> 0 | BV13: =IF(BR13=0, "", BR13/BT13) | BW13: =IF(BR13=0, "", BR13/BS13) | BX13: =IF(BR13=0, "", BR13/BU13)
BR14: =D14+F14+H14+J14+L14+N14+V14+X14+Z14+AB14+AD14+AF14+AZ14+BB14+BD14+BF14+BH14+AH14+P14+R14+AJ14+BJ14+AL14+AN14+AP14+AR14+AT14+AX14+AV14+BL14+T14+BN14+BP14 -> 0 | BS14: =E14+G14+I14+K14+M14+O14+W14+Y14+AA14+AC14+AE14+AG14+BA14+BC14+BE14+BG14+BI14+AI14+Q14+S14+AK14+BK14+AM14+AO14+AQ14+AS14+AU14+AY14+AW14+BM14+U14+BO14+BQ14 -> 0 | BV14: =IF(BR14=0, "", BR14/BT14) | BW14: =IF(BR14=0, "", BR14/BS14) | BX14: =IF(BR14=0, "", BR14/BU14)
BR15: =D15+F15+H15+J15+L15+N15+V15+X15+Z15+AB15+AD15+AF15+AZ15+BB15+BD15+BF15+BH15+AH15+P15+R15+AJ15+BJ15+AL15+AN15+AP15+AR15+AT15+AX15+AV15+BL15+T15+BN15+BP15 -> 0 | BS15: =E15+G15+I15+K15+M15+O15+W15+Y15+AA15+AC15+AE15+AG15+BA15+BC15+BE15+BG15+BI15+AI15+Q15+S15+AK15+BK15+AM15+AO15+AQ15+AS15+AU15+AY15+AW15+BM15+U15+BO15+BQ15 -> 0 | BV15: =IF(BR15=0, "", BR15/BT15) | BW15: =IF(BR15=0, "", BR15/BS15) | BX15: =IF(BR15=0, "", BR15/BU15)
BR16: =D16+F16+H16+J16+L16+N16+V16+X16+Z16+AB16+AD16+AF16+AZ16+BB16+BD16+BF16+BH16+AH16+P16+R16+AJ16+BJ16+AL16+AN16+AP16+AR16+AT16+AX16+AV16+BL16+T16+BN16+BP16 -> 0 | BS16: =E16+G16+I16+K16+M16+O16+W16+Y16+AA16+AC16+AE16+AG16+BA16+BC16+BE16+BG16+BI16+AI16+Q16+S16+AK16+BK16+AM16+AO16+AQ16+AS16+AU16+AY16+AW16+BM16+U16+BO16+BQ16 -> 0 | BV16: =IF(BR16=0, "", BR16/BT16) | BW16: =IF(BR16=0, "", BR16/BS16) | BX16: =IF(BR16=0, "", BR16/BU16)
... BR70: =D70+F70+H70+J70+L70+N70+V70+X70+Z70+AB70+AD70+AF70+AZ70+BB70+BD70+BF70+BH70+AH70+P70+R70+AJ70+BJ70+AL70+AN70+AP70+AR70+AT70+AX70+AV70+BL70+T70+BN70+BP70 -> 0 | BS70: =E70+G70+I70+K70+M70+O70+W70+Y70+AA70+AC70+AE70+AG70+BA70+BC70+BE70+BG70+BI70+AI70+Q70+S70+AK70+BK70+AM70+AO70+AQ70+AS70+AU70+AY70+AW70+BM70+U70+BO70+BQ70 -> 0 | BV70: =IF(BR70=0, "", BR70/BT70) | BW70: =IF(BR70=0, "", BR70/BS70) | BX70: =IF(BR70=0, "", BR70/BU70)
B71: TOTAL | D71: =SUM(D4:D70) -> 0 | E71: =SUM(E4:E70) -> 0 | F71: =SUM(F4:F70) -> 0 | G71: =SUM(G4:G70) -> 0 | H71: =SUM(H4:H70) -> 0 | I71: =SUM(I4:I70) -> 0 | J71: =SUM(J4:J70) -> 0 | K71: =SUM(K4:K70) -> 0 | ... BU71: =SUM(BU4:BU70) -> 0 | BV71: =BR71/BT71 -> #VALUE! | BW71: =BR71/BS71 -> #VALUE! | BX71: =BR71/BU71 -> #VALUE!
B74: No. Of Calls | C74: Line Code | D74: Pax Per Line | E74: Allotments | F74: Pax on Board | G74: Capture Rate | H74: Utilization Rate | I74: Pax Per Call
A75: Royal | B75: =COUNTIF(B4:B70,"*RCL*") -> 0 | C75: RCL | D75: =SUMIF($B$4:$B$70,"RCL",BR4:BR70) -> 0 | E75: =SUMIF($B$4:$B$70,"RCL",BS4:BS70) -> 0 | F75: =SUMIF($B$4:$B$70,"RCL",BT4:BT70) -> 0 | G75: =IF(D75=0, "", D75/F75) | H75: =IF(D75=0, "",D75/E75) | I75: =IF(D75=0, "",D75/B75)
A76: Norwegian | B76: =COUNTIF(B4:B70,"*NCL*") -> 0 | C76: NCL | D76: =SUMIF($B$4:$B$70,"NCL",BR4:BR70) -> 0 | E76: =SUMIF($B$4:$B$70,"NCL",BS4:BS70) -> 0 | F76: =SUMIF($B$4:$B$70,"NCL",BT4:BT70) -> 0 | G76: =IF(D76=0, "", D76/F76) | H76: =IF(D76=0, "",D76/E76) | I76: =IF(D76=0, "",D76/B76)
A77: Disney | B77: =COUNTIF(B4:B70,"*DCL*") -> 0 | C77: DCL | D77: =SUMIF($B$4:$B$70,"DCL",BR4:BR70) -> 0 | E77: =SUMIF($B$4:$B$70,"DCL",BS4:BS70) -> 0 | F77: =SUMIF($B$4:$B$70,"DCL",BT4:BT70) -> 0 | G77: =IF(D77=0, "", D77/F77) | H77: =IF(D77=0, "",D77/E77) | I77: =IF(D77=0, "",D77/B77)
A78: Celebrity | B78: =COUNTIF(B4:B70,"*CEL*") -> 0 | C78: CEL | D78: =SUMIF($B$4:$B$70,"CEL",BR4:BR70) -> 0 | E78: =SUMIF($B$4:$B$70,"CEL",BS4:BS70) -> 0 | F78: =SUMIF($B$4:$B$70,"CEL",BT4:BT70) -> 0 | G78: =IF(D78=0, "", D78/F78) | H78: =IF(D78=0, "",D78/E78) | I78: =IF(D78=0, "",D78/B78)
A79: Carnival | B79: =COUNTIF(B4:B70,"*CCL*") -> 0 | C79: CCL | D79: =SUMIF($B$4:$B$70,"CCL",BR4:BR70) -> 0 | E79: =SUMIF($B$4:$B$70,"CCL",BS4:BS70) -> 0 | F79: =SUMIF($B$4:$B$70,"CCL",BT4:BT70) -> 0 | G79: =IF(D79=0, "", D79/F79) | H79: =IF(D79=0, "",D79/E79) | I79: =IF(D79=0, "",D79/B79)
A80: Princess | B80: =COUNTIF(B4:B70,"*PCL*") -> 0 | C80: PCL | D80: =SUMIF($B$4:$B$70,"PCL",BR4:BR70) -> 0 | E80: =SUMIF($B$4:$B$70,"PCL",BS4:BS70) -> 0 | F80: =SUMIF($B$4:$B$70,"PCL",BT4:BT70) -> 0 | G80: =IF(D80=0, "", D80/F80) | H80: =IF(D80=0, "",D80/E80) | I80: =IF(D80=0, "",D80/B80)
A81: Holland | B81: =COUNTIF(B4:B70,"*HAL*") -> 0 | C81: HAL | D81: =SUMIF($B$4:$B$70,"HAL",BR4:BR70) -> 0 | E81: =SUMIF($B$4:$B$70,"HAL",BS4:BS70) -> 0 | F81: =SUMIF($B$4:$B$70,"HAL",BT4:BT70) -> 0 | G81: =IF(D81=0, "", D81/F81) | H81: =IF(D81=0, "",D81/E81) | I81: =IF(D81=0, "",D81/B81)
A82: Silverseas | B82: =COUNTIF(B4:B70,"*Silver*") -> 0 | C82: Silver | D82: =SUMIF($B$4:$B$70,"Silver",BR4:BR70) -> 0 | E82: =SUMIF($B$4:$B$70,"Silver",BS4:BS70) -> 0 | F82: =SUMIF($B$4:$B$70,"Silver",BT4:BT70) -> 0 | G82: =IF(D82=0, "", D82/F82) | H82: =IF(D82=0, "",D82/E82) | I82: =IF(D82=0, "",D82/B82)
A83: Viking | B83: =COUNTIF(B4:B70,"*Viking*") -> 0 | C83: Viking | D83: =SUMIF($B$4:$B$70,"Viking",BR4:BR70) -> 0 | E83: =SUMIF($B$4:$B$70,"Viking",BS4:BS70) -> 0 | F83: =SUMIF($B$4:$B$70,"Viking",BT4:BT70) -> 0 | G83: =IF(D83=0, "", D83/F83) | H83: =IF(D83=0, "",D83/E83) | I83: =IF(D83=0, "",D83/B83)
A84: Azamara | B84: =COUNTIF(B4:B70,"*Azamara*") -> 0 | C84: Azamara | D84: =SUMIF($B$4:$B$70,"Azamara",BR4:BR70) -> 0 | E84: =SUMIF($B$4:$B$70,"Azamara",BS4:BS70) -> 0 | F84: =SUMIF($B$4:$B$70,"Azamara",BT4:BT70) -> 0 | G84: =IF(D84=0, "", D84/F84) | H84: =IF(D84=0, "",D84/E84) | I84: =IF(D84=0, "",D84/B84)
A85: TUI | B85: =COUNTIF(B4:B70,"*TUI*") -> 0 | C85: TUI | D85: =SUMIF($B$4:$B$70,"TUI",BR4:BR70) -> 0 | E85: =SUMIF($B$4:$B$70,"TUI",BS4:BS70) -> 0 | F85: =SUMIF($B$4:$B$70,"TUI",BT4:BT70) -> 0 | G85: =IF(D85=0, "", D85/F85) | H85: =IF(D85=0, "",D85/E85) | I85: =IF(D85=0, "",D85/B85)
A86: Marella | B86: =COUNTIF(B4:B70,"*Marella*") -> 0 | C86: Marella | D86: =SUMIF($B$4:$B$70,"Marella",BR4:BR70) -> 0 | E86: =SUMIF($B$4:$B$70,"Marella",BS4:BS70) -> 0 | F86: =SUMIF($B$4:$B$70,"Marella",BT4:BT70) -> 0 | G86: =IF(D86=0, "", D86/F86) | H86: =IF(D86=0, "",D86/E86) | I86: =IF(D86=0, "",D86/B86)
A87: MSC | B87: =COUNTIF(B4:B70,"*MSC*") -> 0 | C87: MSC | D87: =SUMIF($B$4:$B$70,"MSC",BR4:BR70) -> 0 | E87: =SUMIF($B$4:$B$70,"MSC",BS4:BS70) -> 0 | F87: =SUMIF($B$4:$B$70,"MSC",BT4:BT70) -> 0 | G87: =IF(D87=0, "", D87/F87) | H87: =IF(D87=0, "",D87/E87) | I87: =IF(D87=0, "",D87/B87)
A88: Regent | B88: =COUNTIF(B4:B70,"*Regent*") -> 0 | C88: Regent | D88: =SUMIF($B$4:$B$70,"Regent",BR4:BR70) -> 0 | E88: =SUMIF($B$4:$B$70,"Regent",BS4:BS70) -> 0 | F88: =SUMIF($B$4:$B$70,"Regent",BT4:BT70) -> 0 | G88: =IF(D88=0, "", D88/F88) | H88: =IF(D88=0, "",D88/E88) | I88: =IF(D88=0, "",D88/B88)
A89: Windstar | B89: =COUNTIF(B5:B71,"*Windstar*") -> 0 | C89: Windstar | D89: =SUMIF($B$4:$B$70,"Windstar",BR4:BR70) -> 0 | E89: =SUMIF($B$4:$B$70,"Windstar",BS4:BS70) -> 0 | F89: =SUMIF($B$4:$B$70,"Windstar",BT4:BT70) -> 0 | G89: =IF(D89=0, "", D89/F89) | H89: =IF(D89=0, "",D89/E89) | I89: =IF(D89=0, "",D89/B89)
A90: Explora | B90: =COUNTIF(B6:B72,"*Explora*") -> 0 | C90: Explora | D90: =SUMIF($B$4:$B$70,"Explora",BR4:BR70) -> 0 | E90: =SUMIF($B$4:$B$70,"Explora",BS4:BS70) -> 0 | F90: =SUMIF($B$4:$B$70,"Explora",BT4:BT70) -> 0 | G90: =IF(D90=0, "", D90/F90) | H90: =IF(D90=0, "",D90/E90) | I90: =IF(D90=0, "",D90/B90)
A91: Cunard | B91: =COUNTIF(B7:B73,"*Cunard*") -> 0 | C91: Cunard | D91: =SUMIF($B$4:$B$70,"Cunard",BR4:BR70) -> 0 | E91: =SUMIF($B$4:$B$70,"Cunard",BS4:BS70) -> 0 | F91: =SUMIF($B$4:$B$70,"Cunard",BT4:BT70) -> 0 | G91: =IF(D91=0, "", D91/F91) | H91: =IF(D91=0, "",D91/E91) | I91: =IF(D91=0, "",D91/B91)
B94: No. Of Calls | D94: Pax Per Line | E94: Allotments | F94: Pax on Board | G94: Capture Rate | H94: Utilization Rate | I94: Pax Per Call
A95: Vista | B95: =COUNTIF(C4:C70,"*Vista*") -> 0 | D95: =SUMIF($C$4:$C$70,"Vista",$BR$4:$BR$70) -> 0 | E95: =SUMIF($C$4:$C$70,"Vista",$BS$4:$BS$70) -> 0 | F95: =SUMIF($C$4:$C$70,"Vista",$BT$4:$BT$70) -> 0 | G95: =IF(D95=0, "", D95/F95) | H95: =IF(D95=0, "",D95/E95) | I95: =IF(D95=0, "",D95/B95)
A96: Conquest | B96: =COUNTIF(C4:C70,"*Conquest*") -> 0 | D96: =SUMIF($C$4:$C$70,"Conquest",$BR$4:$BR$70) -> 0 | E96: =SUMIF($C$4:$C$70,"Conquest",$BS$4:$BS$70) -> 0 | F96: =SUMIF($C$4:$C$70,"Conquest",$BT$4:$BT$70) -> 0 | G96: =IF(D96=0, "", D96/F96) | H96: =IF(D96=0, "",D96/E96) | I96: =IF(D96=0, "",D96/B96)
A97: Glory | B97: =COUNTIF(C4:C70,"*Glory*") -> 0 | D97: =SUMIF($C$4:$C$70,"Glory",$BR$4:$BR$70) -> 0 | E97: =SUMIF($C$4:$C$70,"Glory",$BS$4:$BS$70) -> 0 | F97: =SUMIF($C$4:$C$70,"Glory",$BT$4:$BT$70) -> 0 | G97: =IF(D97=0, "", D97/F97) | H97: =IF(D97=0, "",D97/E97) | I97: =IF(D97=0, "",D97/B97)
A98: Liberty | B98: =COUNTIF(C4:C70,"*Liberty*") -> 0 | D98: =SUMIF($C$4:$C$70,"Liberty",$BR$4:$BR$70) -> 0 | E98: =SUMIF($C$4:$C$70,"Liberty",$BS$4:$BS$70) -> 0 | F98: =SUMIF($C$4:$C$70,"Liberty",$BT$4:$BT$70) -> 0 | G98: =IF(D98=0, "", D98/F98) | H98: =IF(D98=0, "",D98/E98) | I98: =IF(D98=0, "",D98/B98)
...

Sheet Nov 25
A2: DATE | B2: LINE | C2: SHIP NAME | D2: Catamaran Sail & Snorkel | F2: Champagne Adults Only | H2: Invisible Boat Family | BR2: PAX TOTALS, ANALYSIS and RATES
D3: Sold | E3: Allotment | F3: Sold | G3: Allotment | H3: Sold | I3: Allotment | J3: Sold | K3: Allotment | L3: Sold | M3: Allotment | N3: Sold | O3: Allotment | P3: Sold | Q3: Allotment | R3: Sold | S3: Allotment | T3: Sold | U3: Allotment | V3: Sold | W3: Allotment | X3: Sold | Y3: Allotment | Z3: Sold | AA3: Allotment | AB3: Sold | AC3: Allotment | AD3: Sold | AE3: Allotment | AF3: Sold | AG3: Allotment | AH3: Sold | AI3: Allotment | AJ3: Sold | AK3: Allotment | AL3: Sold | AM3: Allotment | AN3: Sold | AO3: Allotment | AP3: Sold | AQ3: Allotment | AR3: Sold | AS3: Allotment | AT3: Sold | AU3: Allotment | AV3: Sold | AW3: Allotment | AX3: Sold | AY3: Allotment | AZ3: Sold | BA3: Allotment | BB3: Sold | BC3: Allotment | BD3: Sold | BE3: Allotment | BF3: Sold | BG3: Allotment | BH3: Sold | BI3: Allotment | BJ3: Sold | BK3: Allotment | BL3: Sold | BM3: Allotment | BN3: Sold | BO3: Allotment | BP3: Sold | BQ3: Allotment | BR3: Chukka Tours (Sold) | BS3: Alloted Pax | BT3: Pax on Board | BU3: Pax on Tour | BV3: Capture Rate | BW3: Utilization Rate | BX3: Market Share
A4: {{date}} | B4: {{cruise_line}} | C4: {{ship_name}} | D4: {{cat_sold}} | E4: {{cat_allot}} | F4: {{champ_sold}} | G4: {{champ_allot}} | H4: {{inv_sold}} | I4: {{inv_allot}} | BR4: =D4+F4+H4+J4+L4+N4+V4+X4+Z4+AB4+AD4+AF4+AZ4+BB4+BD4+BF4+BH4+AH4+P4+R4+AJ4+BJ4+AL4+AN4+AP4+AR4+AT4+AX4+AV4+BL4+T4+BN4+BP4 -> #VALUE! | BS4: =E4+G4+I4+K4+M4+O4+W4+Y4+AA4+AC4+AE4+AG4+BA4+BC4+BE4+BG4+BI4+AI4+Q4+S4+AK4+BK4+AM4+AO4+AQ4+AS4+AU4+AY4+AW4+BM4+U4+BO4+BQ4 -> #VALUE! | BT4: {{pax_on_board}} | BU4: {{pax_on_tour}} | BV4: =IF(BR4=0, "", BR4/BT4) -> #VALUE! | BW4: =IF(BR4=0, "", BR4/BS4) -> #VALUE! | BX4: =IF(BR4=0, "", BR4/BU4) -> #VALUE!
BR5: =D5+F5+H5+J5+L5+N5+V5+X5+Z5+AB5+AD5+AF5+AZ5+BB5+BD5+BF5+BH5+AH5+P5+R5+AJ5+BJ5+AL5+AN5+AP5+AR5+AT5+AX5+AV5+BL5+T5+BN5+BP5 -> 0 | BS5: =E5+G5+I5+K5+M5+O5+W5+Y5+AA5+AC5+AE5+AG5+BA5+BC5+BE5+BG5+BI5+AI5+Q5+S5+AK5+BK5+AM5+AO5+AQ5+AS5+AU5+AY5+AW5+BM5+U5+BO5+BQ5 -> 0 | BV5: =IF(BR5=0, "", BR5/BT5) | BW5: =IF(BR5=0, "", BR5/BS5) | BX5: =IF(BR5=0, "", BR5/BU5)
BR6: =D6+F6+H6+J6+L6+N6+V6+X6+Z6+AB6+AD6+AF6+AZ6+BB6+BD6+BF6+BH6+AH6+P6+R6+AJ6+BJ6+AL6+AN6+AP6+AR6+AT6+AX6+AV6+BL6+T6+BN6+BP6 -> 0 | BS6: =E6+G6+I6+K6+M6+O6+W6+Y6+AA6+AC6+AE6+AG6+BA6+BC6+BE6+BG6+BI6+AI6+Q6+S6+AK6+BK6+AM6+AO6+AQ6+AS6+AU6+AY6+AW6+BM6+U6+BO6+BQ6 -> 0 | BV6: =IF(BR6=0, "", BR6/BT6) | BW6: =IF(BR6=0, "", BR6/BS6) | BX6: =IF(BR6=0, "", BR6/BU6)
BR7: =D7+F7+H7+J7+L7+N7+V7+X7+Z7+AB7+AD7+AF7+AZ7+BB7+BD7+BF7+BH7+AH7+P7+R7+AJ7+BJ7+AL7+AN7+AP7+AR7+AT7+AX7+AV7+BL7+T7+BN7+BP7 -> 0 | BS7: =E7+G7+I7+K7+M7+O7+W7+Y7+AA7+AC7+AE7+AG7+BA7+BC7+BE7+BG7+BI7+AI7+Q7+S7+AK7+BK7+AM7+AO7+AQ7+AS7+AU7+AY7+AW7+BM7+U7+BO7+BQ7 -> 0 | BV7: =IF(BR7=0, "", BR7/BT7) | BW7: =IF(BR7=0, "", BR7/BS7) | BX7: =IF(BR7=0, "", BR7/BU7)
BR8: =D8+F8+H8+J8+L8+N8+V8+X8+Z8+AB8+AD8+AF8+AZ8+BB8+BD8+BF8+BH8+AH8+P8+R8+AJ8+BJ8+AL8+AN8+AP8+AR8+AT8+AX8+AV8+BL8+T8+BN8+BP8 -> 0 | BS8: =E8+G8+I8+K8+M8+O8+W8+Y8+AA8+AC8+AE8+AG8+BA8+BC8+BE8+BG8+BI8+AI8+Q8+S8+AK8+BK8+AM8+AO8+AQ8+AS8+AU8+AY8+AW8+BM8+U8+BO8+BQ8 -> 0 | BV8: =IF(BR8=0, "", BR8/BT8) | BW8: =IF(BR8=0, "", BR8/BS8) | BX8: =IF(BR8=0, "", BR8/BU8)
BR9: =D9+F9+H9+J9+L9+N9+V9+X9+Z9+AB9+AD9+AF9+AZ9+BB9+BD9+BF9+BH9+AH9+P9+R9+AJ9+BJ9+AL9+AN9+AP9+AR9+AT9+AX9+AV9+BL9+T9+BN9+BP9 -> 0 | BS9: =E9+G9+I9+K9+M9+O9+W9+Y9+AA9+AC9+AE9+AG9+BA9+BC9+BE9+BG9+BI9+AI9+Q9+S9+AK9+BK9+AM9+AO9+AQ9+AS9+AU9+AY9+AW9+BM9+U9+BO9+BQ9 -> 0 | BV9: =IF(BR9=0, "", BR9/BT9) | BW9: =IF(BR9=0, "", BR9/BS9) | BX9: =IF(BR9=0, "", BR9/BU9)
BR10: =D10+F10+H10+J10+L10+N10+V10+X10+Z10+AB10+AD10+AF10+AZ10+BB10+BD10+BF10+BH10+AH10+P10+R10+AJ10+BJ10+AL10+AN10+AP10+AR10+AT10+AX10+AV10+BL10+T10+BN10+BP10 -> 0 | BS10: =E10+G10+I10+K10+M10+O10+W10+Y10+AA10+AC10+AE10+AG10+BA10+BC10+BE10+BG10+BI10+AI10+Q10+S10+AK10+BK10+AM10+AO10+AQ10+AS10+AU10+AY10+AW10+BM10+U10+BO10+BQ10 -> 0 | BV10: =IF(BR10=0, "", BR10/BT10) | BW10: =IF(BR10=0, "", BR10/BS10) | BX10: =IF(BR10=0, "", BR10/BU10)
BR11: =D11+F11+H11+J11+L11+N11+V11+X11+Z11+AB11+AD11+AF11+AZ11+BB11+BD11+BF11+BH11+AH11+P11+R11+AJ11+BJ11+AL11+AN11+AP11+AR11+AT11+AX11+AV11+BL11+T11+BN11+BP11 -> 0 | BS11: =E11+G11+I11+K11+M11+O11+W11+Y11+AA11+AC11+AE11+AG11+BA11+BC11+BE11+BG11+BI11+AI11+Q11+S11+AK11+BK11+AM11+AO11+AQ11+AS11+AU11+AY11+AW11+BM11+U11+BO11+BQ11 -> 0 | BV11: =IF(BR11=0, "", BR11/BT11) | BW11: =IF(BR11=0, "", BR11/BS11) | BX11: =IF(BR11=0, "", BR11/BU11)
BR12: =D12+F12+H12+J12+L12+N12+V12+X12+Z12+AB12+AD12+AF12+AZ12+BB12+BD12+BF12+BH12+AH12+P12+R12+AJ12+BJ12+AL12+AN12+AP12+AR12+AT12+AX12+AV12+BL12+T12+BN12+BP12 -> 0 | BS12: =E12+G12+I12+K12+M12+O12+W12+Y12+AA12+AC12+AE12+AG12+BA12+BC12+BE12+BG12+BI12+AI12+Q12+S12+AK12+BK12+AM12+AO12+AQ12+AS12+AU12+AY12+AW12+BM12+U12+BO12+BQ12 -> 0 | BV12: =IF(BR12=0, "", BR12/BT12) | BW12: =IF(BR12=0, "", BR12/BS12) | BX12: =IF(BR12=0, "", BR12/BU12)
BR13: =D13+F13+H13+J13+L13+N13+V13+X13+Z13+AB13+AD13+AF13+AZ13+BB13+BD13+BF13+BH13+AH13+P13+R13+AJ13+BJ13+AL13+AN13+AP13+AR13+AT13+AX13+AV13+BL13+T13+BN13+BP13 -> 0 | BS13: =E13+G13+I13+K13+M13+O13+W13+Y13+AA13+AC13+AE13+AG13+BA13+BC13+BE13+BG13+BI13+AI13+Q13+S13+AK13+BK13+AM13+AO13+AQ13+AS13+AU13+AY13+AW13+BM13+U13+BO13+BQ13 -> 0 | BV13: =IF(BR13=0, "", BR13/BT13) | BW13: =IF(BR13=0, "", BR13/BS13) | BX13: =IF(BR13=0, "", BR13/BU13)
BR14: =D14+F14+H14+J14+L14+N14+V14+X14+Z14+AB14+AD14+AF14+AZ14+BB14+BD14+BF14+BH14+AH14+P14+R14+AJ14+BJ14+AL14+AN14+AP14+AR14+AT14+AX14+AV14+BL14+T14+BN14+BP14 -> 0 | BS14: =E14+G14+I14+K14+M14+O14+W14+Y14+AA14+AC14+AE14+AG14+BA14+BC14+BE14+BG14+BI14+AI14+Q14+S14+AK14+BK14+AM14+AO14+AQ14+AS14+AU14+AY14+AW14+BM14+U14+BO14+BQ14 -> 0 | BV14: =IF(BR14=0, "", BR14/BT14) | BW14: =IF(BR14=0, "", BR14/BS14) | BX14: =IF(BR14=0, "", BR14/BU14)
BR15: =D15+F15+H15+J15+L15+N15+V15+X15+Z15+AB15+AD15+AF15+AZ15+BB15+BD15+BF15+BH15+AH15+P15+R15+AJ15+BJ15+AL15+AN15+AP15+AR15+AT15+AX15+AV15+BL15+T15+BN15+BP15 -> 0 | BS15: =E15+G15+I15+K15+M15+O15+W15+Y15+AA15+AC15+AE15+AG15+BA15+BC15+BE15+BG15+BI15+AI15+Q15+S15+AK15+BK15+AM15+AO15+AQ15+AS15+AU15+AY15+AW15+BM15+U15+BO15+BQ15 -> 0 | BV15: =IF(BR15=0, "", BR15/BT15) | BW15: =IF(BR15=0, "", BR15/BS15) | BX15: =IF(BR15=0, "", BR15/BU15)
BR16: =D16+F16+H16+J16+L16+N16+V16+X16+Z16+AB16+AD16+AF16+AZ16+BB16+BD16+BF16+BH16+AH16+P16+R16+AJ16+BJ16+AL16+AN16+AP16+AR16+AT16+AX16+AV16+BL16+T16+BN16+BP16 -> 0 | BS16: =E16+G16+I16+K16+M16+O16+W16+Y16+AA16+AC16+AE16+AG16+BA16+BC16+BE16+BG16+BI16+AI16+Q16+S16+AK16+BK16+AM16+AO16+AQ16+AS16+AU16+AY16+AW16+BM16+U16+BO16+BQ16 -> 0 | BV16: =IF(BR16=0, "", BR16/BT16) | BW16: =IF(BR16=0, "", BR16/BS16) | BX16: =IF(BR16=0, "", BR16/BU16)
... BR70: =D70+F70+H70+J70+L70+N70+V70+X70+Z70+AB70+AD70+AF70+AZ70+BB70+BD70+BF70+BH70+AH70+P70+R70+AJ70+BJ70+AL70+AN70+AP70+AR70+AT70+AX70+AV70+BL70+T70+BN70+BP70 -> 0 | BS70: =E70+G70+I70+K70+M70+O70+W70+Y70+AA70+AC70+AE70+AG70+BA70+BC70+BE70+BG70+BI70+AI70+Q70+S70+AK70+BK70+AM70+AO70+AQ70+AS70+AU70+AY70+AW70+BM70+U70+BO70+BQ70 -> 0 | BV70: =IF(BR70=0, "", BR70/BT70) | BW70: =IF(BR70=0, "", BR70/BS70) | BX70: =IF(BR70=0, "", BR70/BU70)
B71: TOTAL | D71: =SUM(D4:D70) -> 0 | E71: =SUM(E4:E70) -> 0 | F71: =SUM(F4:F70) -> 0 | G71: =SUM(G4:G70) -> 0 | H71: =SUM(H4:H70) -> 0 | I71: =SUM(I4:I70) -> 0 | J71: =SUM(J4:J70) -> 0 | K71: =SUM(K4:K70) -> 0 | ... BU71: =SUM(BU4:BU70) -> 0 | BV71: =BR71/BT71 -> #VALUE! | BW71: =BR71/BS71 -> #VALUE! | BX71: =BR71/BU71 -> #VALUE!
B74: No. Of Calls | C74: Line Code | D74: Pax Per Line | E74: Allotments | F74: Pax on Board | G74: Capture Rate | H74: Utilization Rate
A75: Royal | B75: =COUNTIF(B4:B70,"*RCL*") -> 0 | C75: RCL | D75: =SUMIF($B$4:$B$70,"RCL",BR4:BR70) -> 0 | E75: =SUMIF($B$4:$B$70,"RCL",BS4:BS70) -> 0 | F75: =SUMIF($B$4:$B$70,"RCL",BT4:BT70) -> 0 | G75: =IF(D75=0, "", D75/F75) | H75: =IF(D75=0, "",D75/E75) | I75: =IF(D75=0, "",D75/B75)
A76: Norwegian | B76: =COUNTIF(B4:B70,"*NCL*") -> 0 | C76: NCL | D76: =SUMIF($B$4:$B$70,"NCL",BR4:BR70) -> 0 | E76: =SUMIF($B$4:$B$70,"NCL",BS4:BS70) -> 0 | F76: =SUMIF($B$4:$B$70,"NCL",BT4:BT70) -> 0 | G76: =IF(D76=0, "", D76/F76) | H76: =IF(D76=0, "",D76/E76)
A77: Disney | B77: =COUNTIF(B4:B70,"*DCL*") -> 0 | C77: DCL | D77: =SUMIF($B$4:$B$70,"DCL",BR4:BR70) -> 0 | E77: =SUMIF($B$4:$B$70,"DCL",BS4:BS70) -> 0 | F77: =SUMIF($B$4:$B$70,"DCL",BT4:BT70) -> 0 | G77: =IF(D77=0, "", D77/F77) | H77: =IF(D77=0, "",D77/E77)
A78: Celebrity | B78: =COUNTIF(B4:B70,"*CEL*") -> 0 | C78: CEL | D78: =SUMIF($B$4:$B$70,"CEL",BR4:BR70) -> 0 | E78: =SUMIF($B$4:$B$70,"CEL",BS4:BS70) -> 0 | F78: =SUMIF($B$4:$B$70,"CEL",BT4:BT70) -> 0 | G78: =IF(D78=0, "", D78/F78) | H78: =IF(D78=0, "",D78/E78)
A79: Carnival | B79: =COUNTIF(B4:B70,"*CCL*") -> 0 | C79: CCL | D79: =SUMIF($B$4:$B$70,"CCL",BR4:BR70) -> 0 | E79: =SUMIF($B$4:$B$70,"CCL",BS4:BS70) -> 0 | F79: =SUMIF($B$4:$B$70,"CCL",BT4:BT70) -> 0 | G79: =IF(D79=0, "", D79/F79) | H79: =IF(D79=0, "",D79/E79)
A80: Princess | B80: =COUNTIF(B4:B70,"*PCL*") -> 0 | C80: PCL | D80: =SUMIF($B$4:$B$70,"PCL",BR4:BR70) -> 0 | E80: =SUMIF($B$4:$B$70,"PCL",BS4:BS70) -> 0 | F80: =SUMIF($B$4:$B$70,"PCL",BT4:BT70) -> 0 | G80: =IF(D80=0, "", D80/F80) | H80: =IF(D80=0, "",D80/E80)
A81: Holland | B81: =COUNTIF(B4:B70,"*HAL*") -> 0 | C81: HAL | D81: =SUMIF($B$4:$B$70,"HAL",BR4:BR70) -> 0 | E81: =SUMIF($B$4:$B$70,"HAL",BS4:BS70) -> 0 | F81: =SUMIF($B$4:$B$70,"HAL",BT4:BT70) -> 0 | G81: =IF(D81=0, "", D81/F81) | H81: =IF(D81=0, "",D81/E81)
A82: Silverseas | B82: =COUNTIF(B4:B70,"*Silver*") -> 0 | C82: Silver | D82: =SUMIF($B$4:$B$70,"Silver",BR4:BR70) -> 0 | E82: =SUMIF($B$4:$B$70,"Silver",BS4:BS70) -> 0 | F82: =SUMIF($B$4:$B$70,"Silver",BT4:BT70) -> 0 | G82: =IF(D82=0, "", D82/F82) | H82: =IF(D82=0, "",D82/E82)
A83: Viking | B83: =COUNTIF(B4:B70,"*Viking*") -> 0 | C83: Viking | D83: =SUMIF($B$4:$B$70,"Viking",BR4:BR70) -> 0 | E83: =SUMIF($B$4:$B$70,"Viking",BS4:BS70) -> 0 | F83: =SUMIF($B$4:$B$70,"Viking",BT4:BT70) -> 0 | G83: =IF(D83=0, "", D83/F83) | H83: =IF(D83=0, "",D83/E83)
A84: Azamara | B84: =COUNTIF(B4:B70,"*Azamara*") -> 0 | C84: Azamara | D84: =SUMIF($B$4:$B$70,"Azamara",BR4:BR70) -> 0 | E84: =SUMIF($B$4:$B$70,"Azamara",BS4:BS70) -> 0 | F84: =SUMIF($B$4:$B$70,"Azamara",BT4:BT70) -> 0 | G84: =IF(D84=0, "", D84/F84) | H84: =IF(D84=0, "",D84/E84)
A85: TUI | B85: =COUNTIF(B4:B70,"*TUI*") -> 0 | C85: TUI | D85: =SUMIF($B$4:$B$70,"TUI",BR4:BR70) -> 0 | E85: =SUMIF($B$4:$B$70,"TUI",BS4:BS70) -> 0 | F85: =SUMIF($B$4:$B$70,"TUI",BT4:BT70) -> 0 | G85: =IF(D85=0, "", D85/F85) | H85: =IF(D85=0, "",D85/E85)
A86: Marella | B86: =COUNTIF(B4:B70,"*Marella*") -> 0 | C86: Marella | D86: =SUMIF($B$4:$B$70,"Marella",BR4:BR70) -> 0 | E86: =SUMIF($B$4:$B$70,"Marella",BS4:BS70) -> 0 | F86: =SUMIF($B$4:$B$70,"Marella",BT4:BT70) -> 0 | G86: =IF(D86=0, "", D86/F86) | H86: =IF(D86=0, "",D86/E86)
A87: MSC | B87: =COUNTIF(B4:B70,"*MSC*") -> 0 | C87: MSC | D87: =SUMIF($B$4:$B$70,"MSC",BR4:BR70) -> 0 | E87: =SUMIF($B$4:$B$70,"MSC",BS4:BS70) -> 0 | F87: =SUMIF($B$4:$B$70,"MSC",BT4:BT70) -> 0 | G87: =IF(D87=0, "", D87/F87) | H87: =IF(D87=0, "",D87/E87)
A88: Regent | B88: =COUNTIF(B4:B70,"*Regent*") -> 0 | C88: Regent | D88: =SUMIF($B$4:$B$70,"Regent",BR4:BR70) -> 0 | E88: =SUMIF($B$4:$B$70,"Regent",BS4:BS70) -> 0 | F88: =SUMIF($B$4:$B$70,"Regent",BT4:BT70) -> 0 | G88: =IF(D88=0, "", D88/F88) | H88: =IF(D88=0, "",D88/E88)
A89: Windstar | B89: =COUNTIF(B5:B71,"*Windstar*") -> 0 | C89: Windstar | D89: =SUMIF($B$4:$B$70,"Windstar",BR4:BR70) -> 0 | E89: =SUMIF($B$4:$B$70,"Windstar",BS4:BS70) -> 0 | F89: =SUMIF($B$4:$B$70,"Windstar",BT4:BT70) -> 0 | G89: =IF(D89=0, "", D89/F89) | H89: =IF(D89=0, "",D89/E89)
A90: Explora | B90: =COUNTIF(B6:B72,"*Explora*") -> 0 | C90: Explora | D90: =SUMIF($B$4:$B$70,"Explora",BR4:BR70) -> 0 | E90: =SUMIF($B$4:$B$70,"Explora",BS4:BS70) -> 0 | F90: =SUMIF($B$4:$B$70,"Explora",BT4:BT70) -> 0 | G90: =IF(D90=0, "", D90/F90) | H90: =IF(D90=0, "",D90/E90)
A91: Cunard | B91: =COUNTIF(B7:B73,"*Cunard*") -> 0 | C91: Cunard | D91: =SUMIF($B$4:$B$70,"Cunard",BR4:BR70) -> 0 | E91: =SUMIF($B$4:$B$70,"Cunard",BS4:BS70) -> 0 | F91: =SUMIF($B$4:$B$70,"Cunard",BT4:BT70) -> 0 | G91: =IF(D91=0, "", D91/F91) | H91: =IF(D91=0, "",D91/E91)
B94: No. Of Calls | D94: Pax Per Line | E94: Allotments | F94: Pax on Board | G94: Capture Rate | H94: Utilization Rate
A95: Vista | B95: =COUNTIF(C4:C70,"*Vista*") -> 0 | D95: =SUMIF($C$4:$C$70,"Vista",$BR$4:$BR$70) -> 0 | E95: =SUMIF($C$4:$C$70,"Vista",$BS$4:$BS$70) -> 0 | F95: =SUMIF($C$4:$C$70,"Vista",$BT$4:$BT$70) -> 0 | G95: =IF(D95=0, "", D95/F95) | H95: =IF(D95=0, "",D95/E95) | I95: =IF(D95=0, "",D95/B95)
A96: Conquest | B96: =COUNTIF(C4:C70,"*Conquest*") -> 0 | D96: =SUMIF($C$4:$C$70,"Conquest",$BR$4:$BR$70) -> 0 | E96: =SUMIF($C$4:$C$70,"Conquest",$BS$4:$BS$70) -> 0 | F96: =SUMIF($C$4:$C$70,"Conquest",$BT$4:$BT$70) -> 0 | G96: =IF(D96=0, "", D96/F96) | H96: =IF(D96=0, "",D96/E96) | I96: =IF(D96=0, "",D96/B96)
A97: Glory | B97: =COUNTIF(C4:C70,"*Glory*") -> 0 | D97: =SUMIF($C$4:$C$70,"Glory",$BR$4:$BR$70) -> 0 | E97: =SUMIF($C$4:$C$70,"Glory",$BS$4:$BS$70) -> 0 | F97: =SUMIF($C$4:$C$70,"Glory",$BT$4:$BT$70) -> 0 | G97: =IF(D97=0, "", D97/F97) | H97: =IF(D97=0, "",D97/E97) | I97: =IF(D97=0, "",D97/B97)
A98: Liberty | B98: =COUNTIF(C4:C70,"*Liberty*") -> 0 | D98: =SUMIF($C$4:$C$70,"Liberty",$BR$4:$BR$70) -> 0 | E98: =SUMIF($C$4:$C$70,"Liberty",$BS$4:$BS$70) -> 0 | F98: =SUMIF($C$4:$C$70,"Liberty",$BT$4:$BT$70) -> 0 | G98: =IF(D98=0, "", D98/F98) | H98: =IF(D98=0, "",D98/E98) | I98: =IF(D98=0, "",D98/B98)
...

Sheet Dec 25
A2: DATE | B2: LINE | C2: SHIP NAME | D2: Catamaran Sail & Snorkel | F2: Champagne Adults Only | H2: Invisible Boat Family | BR2: PAX TOTALS, ANALYSIS and RATES
D3: Sold | E3: Allotment | F3: Sold | G3: Allotment | H3: Sold | I3: Allotment | J3: Sold | K3: Allotment | L3: Sold | M3: Allotment | N3: Sold | O3: Allotment | P3: Sold | Q3: Allotment | R3: Sold | S3: Allotment | T3: Sold | U3: Allotment | V3: Sold | W3: Allotment | X3: Sold | Y3: Allotment | Z3: Sold | AA3: Allotment | AB3: Sold | AC3: Allotment | AD3: Sold | AE3: Allotment | AF3: Sold | AG3: Allotment | AH3: Sold | AI3: Allotment | AJ3: Sold | AK3: Allotment | AL3: Sold | AM3: Allotment | AN3: Sold | AO3: Allotment | AP3: Sold | AQ3: Allotment | AR3: Sold | AS3: Allotment | AT3: Sold | AU3: Allotment | AV3: Sold | AW3: Allotment | AX3: Sold | AY3: Allotment | AZ3: Sold | BA3: Allotment | BB3: Sold | BC3: Allotment | BD3: Sold | BE3: Allotment | BF3: Sold | BG3: Allotment | BH3: Sold | BI3: Allotment | BJ3: Sold | BK3: Allotment | BL3: Sold | BM3: Allotment | BN3: Sold | BO3: Allotment | BP3: Sold | BQ3: Allotment | BR3: Chukka Tours (Sold) | BS3: Alloted Pax | BT3: Pax on Board | BU3: Pax on Tour | BV3: Capture Rate | BW3: Utilization Rate | BX3: Market Share
A4: {{date}} | B4: {{cruise_line}} | C4: {{ship_name}} | D4: {{cat_sold}} | E4: {{cat_allot}} | F4: {{champ_sold}} | G4: {{champ_allot}} | H4: {{inv_sold}} | I4: {{inv_allot}} | BR4: =D4+F4+H4+J4+L4+N4+V4+X4+Z4+AB4+AD4+AF4+AZ4+BB4+BD4+BF4+BH4+AH4+P4+R4+AJ4+BJ4+AL4+AN4+AP4+AR4+AT4+AX4+AV4+BL4+T4+BN4+BP4 -> #VALUE! | BS4: =E4+G4+I4+K4+M4+O4+W4+Y4+AA4+AC4+AE4+AG4+BA4+BC4+BE4+BG4+BI4+AI4+Q4+S4+AK4+BK4+AM4+AO4+AQ4+AS4+AU4+AY4+AW4+BM4+U4+BO4+BQ4 -> #VALUE! | BT4: {{pax_on_board}} | BU4: {{pax_on_tour}} | BV4: =IF(BR4=0, "", BR4/BT4) -> #VALUE! | BW4: =IF(BR4=0, "", BR4/BS4) -> #VALUE! | BX4: =IF(BR4=0, "", BR4/BU4) -> #VALUE!
BR5: =D5+F5+H5+J5+L5+N5+V5+X5+Z5+AB5+AD5+AF5+AZ5+BB5+BD5+BF5+BH5+AH5+P5+R5+AJ5+BJ5+AL5+AN5+AP5+AR5+AT5+AX5+AV5+BL5+T5+BN5+BP5 -> 0 | BS5: =E5+G5+I5+K5+M5+O5+W5+Y5+AA5+AC5+AE5+AG5+BA5+BC5+BE5+BG5+BI5+AI5+Q5+S5+AK5+BK5+AM5+AO5+AQ5+AS5+AU5+AY5+AW5+BM5+U5+BO5+BQ5 -> 0 | BV5: =IF(BR5=0, "", BR5/BT5) | BW5: =IF(BR5=0, "", BR5/BS5) | BX5: =IF(BR5=0, "", BR5/BU5)
BR6: =D6+F6+H6+J6+L6+N6+V6+X6+Z6+AB6+AD6+AF6+AZ6+BB6+BD6+BF6+BH6+AH6+P6+R6+AJ6+BJ6+AL6+AN6+AP6+AR6+AT6+AX6+AV6+BL6+T6+BN6+BP6 -> 0 | BS6: =E6+G6+I6+K6+M6+O6+W6+Y6+AA6+AC6+AE6+AG6+BA6+BC6+BE6+BG6+BI6+AI6+Q6+S6+AK6+BK6+AM6+AO6+AQ6+AS6+AU6+AY6+AW6+BM6+U6+BO6+BQ6 -> 0 | BV6: =IF(BR6=0, "", BR6/BT6) | BW6: =IF(BR6=0, "", BR6/BS6) | BX6: =IF(BR6=0, "", BR6/BU6)
BR7: =D7+F7+H7+J7+L7+N7+V7+X7+Z7+AB7+AD7+AF7+AZ7+BB7+BD7+BF7+BH7+AH7+P7+R7+AJ7+BJ7+AL7+AN7+AP7+AR7+AT7+AX7+AV7+BL7+T7+BN7+BP7 -> 0 | BS7: =E7+G7+I7+K7+M7+O7+W7+Y7+AA7+AC7+AE7+AG7+BA7+BC7+BE7+BG7+BI7+AI7+Q7+S7+AK7+BK7+AM7+AO7+AQ7+AS7+AU7+AY7+AW7+BM7+U7+BO7+BQ7 -> 0 | BV7: =IF(BR7=0, "", BR7/BT7) | BW7: =IF(BR7=0, "", BR7/BS7) | BX7: =IF(BR7=0, "", BR7/BU7)
BR8: =D8+F8+H8+J8+L8+N8+V8+X8+Z8+AB8+AD8+AF8+AZ8+BB8+BD8+BF8+BH8+AH8+P8+R8+AJ8+BJ8+AL8+AN8+AP8+AR8+AT8+AX8+AV8+BL8+T8+BN8+BP8 -> 0 | BS8: =E8+G8+I8+K8+M8+O8+W8+Y8+AA8+AC8+AE8+AG8+BA8+BC8+BE8+BG8+BI8+AI8+Q8+S8+AK8+BK8+AM8+AO8+AQ8+AS8+AU8+AY8+AW8+BM8+U8+BO8+BQ8 -> 0 | BV8: =IF(BR8=0, "", BR8/BT8) | BW8: =IF(BR8=0, "", BR8/BS8) | BX8: =IF(BR8=0, "", BR8/BU8)
BR9: =D9+F9+H9+J9+L9+N9+V9+X9+Z9+AB9+AD9+AF9+AZ9+BB9+BD9+BF9+BH9+AH9+P9+R9+AJ9+BJ9+AL9+AN9+AP9+AR9+AT9+AX9+AV9+BL9+T9+BN9+BP9 -> 0 | BS9: =E9+G9+I9+K9+M9+O9+W9+Y9+AA9+AC9+AE9+AG9+BA9+BC9+BE9+BG9+BI9+AI9+Q9+S9+AK9+BK9+AM9+AO9+AQ9+AS9+AU9+AY9+AW9+BM9+U9+BO9+BQ9 -> 0 | BV9: =IF(BR9=0, "", BR9/BT9) | BW9: =IF(BR9=0, "", BR9/BS9) | BX9: =IF(BR9=0, "", BR9/BU9)
BR10: =D10+F10+H10+J10+L10+N10+V10+X10+Z10+AB10+AD10+AF10+AZ10+BB10+BD10+BF10+BH10+AH10+P10+R10+AJ10+BJ10+AL10+AN10+AP10+AR10+AT10+AX10+AV10+BL10+T10+BN10+BP10 -> 0 | BS10: =E10+G10+I10+K10+M10+O10+W10+Y10+AA10+AC10+AE10+AG10+BA10+BC10+BE10+BG10+BI10+AI10+Q10+S10+AK10+BK10+AM10+AO10+AQ10+AS10+AU10+AY10+AW10+BM10+U10+BO10+BQ10 -> 0 | BV10: =IF(BR10=0, "", BR10/BT10) | BW10: =IF(BR10=0, "", BR10/BS10) | BX10: =IF(BR10=0, "", BR10/BU10)
BR11: =D11+F11+H11+J11+L11+N11+V11+X11+Z11+AB11+AD11+AF11+AZ11+BB11+BD11+BF11+BH11+AH11+P11+R11+AJ11+BJ11+AL11+AN11+AP11+AR11+AT11+AX11+AV11+BL11+T11+BN11+BP11 -> 0 | BS11: =E11+G11+I11+K11+M11+O11+W11+Y11+AA11+AC11+AE11+AG11+BA11+BC11+BE11+BG11+BI11+AI11+Q11+S11+AK11+BK11+AM11+AO11+AQ11+AS11+AU11+AY11+AW11+BM11+U11+BO11+BQ11 -> 0 | BV11: =IF(BR11=0, "", BR11/BT11) | BW11: =IF(BR11=0, "", BR11/BS11) | BX11: =IF(BR11=0, "", BR11/BU11)
BR12: =D12+F12+H12+J12+L12+N12+V12+X12+Z12+AB12+AD12+AF12+AZ12+BB12+BD12+BF12+BH12+AH12+P12+R12+AJ12+BJ12+AL12+AN12+AP12+AR12+AT12+AX12+AV12+BL12+T12+BN12+BP12 -> 0 | BS12: =E12+G12+I12+K12+M12+O12+W12+Y12+AA12+AC12+AE12+AG12+BA12+BC12+BE12+BG12+BI12+AI12+Q12+S12+AK12+BK12+AM12+AO12+AQ12+AS12+AU12+AY12+AW12+BM12+U12+BO12+BQ12 -> 0 | BV12: =IF(BR12=0, "", BR12/BT12) | BW12: =IF(BR12=0, "", BR12/BS12) | BX12: =IF(BR12=0, "", BR12/BU12)
BR13: =D13+F13+H13+J13+L13+N13+V13+X13+Z13+AB13+AD13+AF13+AZ13+BB13+BD13+BF13+BH13+AH13+P13+R13+AJ13+BJ13+AL13+AN13+AP13+AR13+AT13+AX13+AV13+BL13+T13+BN13+BP13 -> 0 | BS13: =E13+G13+I13+K13+M13+O13+W13+Y13+AA13+AC13+AE13+AG13+BA13+BC13+BE13+BG13+BI13+AI13+Q13+S13+AK13+BK13+AM13+AO13+AQ13+AS13+AU13+AY13+AW13+BM13+U13+BO13+BQ13 -> 0 | BV13: =IF(BR13=0, "", BR13/BT13) | BW13: =IF(BR13=0, "", BR13/BS13) | BX13: =IF(BR13=0, "", BR13/BU13)
BR14: =D14+F14+H14+J14+L14+N14+V14+X14+Z14+AB14+AD14+AF14+AZ14+BB14+BD14+BF14+BH14+AH14+P14+R14+AJ14+BJ14+AL14+AN14+AP14+AR14+AT14+AX14+AV14+BL14+T14+BN14+BP14 -> 0 | BS14: =E14+G14+I14+K14+M14+O14+W14+Y14+AA14+AC14+AE14+AG14+BA14+BC14+BE14+BG14+BI14+AI14+Q14+S14+AK14+BK14+AM14+AO14+AQ14+AS14+AU14+AY14+AW14+BM14+U14+BO14+BQ14 -> 0 | BV14: =IF(BR14=0, "", BR14/BT14) | BW14: =IF(BR14=0, "", BR14/BS14) | BX14: =IF(BR14=0, "", BR14/BU14)
BR15: =D15+F15+H15+J15+L15+N15+V15+X15+Z15+AB15+AD15+AF15+AZ15+BB15+BD15+BF15+BH15+AH15+P15+R15+AJ15+BJ15+AL15+AN15+AP15+AR15+AT15+AX15+AV15+BL15+T15+BN15+BP15 -> 0 | BS15: =E15+G15+I15+K15+M15+O15+W15+Y15+AA15+AC15+AE15+AG15+BA15+BC15+BE15+BG15+BI15+AI15+Q15+S15+AK15+BK15+AM15+AO15+AQ15+AS15+AU15+AY15+AW15+BM15+U15+BO15+BQ15 -> 0 | BV15: =IF(BR15=0, "", BR15/BT15) | BW15: =IF(BR15=0, "", BR15/BS15) | BX15: =IF(BR15=0, "", BR15/BU15)
BR16: =D16+F16+H16+J16+L16+N16+V16+X16+Z16+AB16+AD16+AF16+AZ16+BB16+BD16+BF16+BH16+AH16+P16+R16+AJ16+BJ16+AL16+AN16+AP16+AR16+AT16+AX16+AV16+BL16+T16+BN16+BP16 -> 0 | BS16: =E16+G16+I16+K16+M16+O16+W16+Y16+AA16+AC16+AE16+AG16+BA16+BC16+BE16+BG16+BI16+AI16+Q16+S16+AK16+BK16+AM16+AO16+AQ16+AS16+AU16+AY16+AW16+BM16+U16+BO16+BQ16 -> 0 | BV16: =IF(BR16=0, "", BR16/BT16) | BW16: =IF(BR16=0, "", BR16/BS16) | BX16: =IF(BR16=0, "", BR16/BU16)
... BR70: =D70+F70+H70+J70+L70+N70+V70+X70+Z70+AB70+AD70+AF70+AZ70+BB70+BD70+BF70+BH70+AH70+P70+R70+AJ70+BJ70+AL70+AN70+AP70+AR70+AT70+AX70+AV70+BL70+T70+BN70+BP70 -> 0 | BS70: =E70+G70+I70+K70+M70+O70+W70+Y70+AA70+AC70+AE70+AG70+BA70+BC70+BE70+BG70+BI70+AI70+Q70+S70+AK70+BK70+AM70+AO70+AQ70+AS70+AU70+AY70+AW70+BM70+U70+BO70+BQ70 -> 0 | BV70: =IF(BR70=0, "", BR70/BT70) | BW70: =IF(BR70=0, "", BR70/BS70) | BX70: =IF(BR70=0, "", BR70/BU70)
B71: TOTAL | D71: =SUM(D4:D70) -> 0 | E71: =SUM(E4:E70) -> 0 | F71: =SUM(F4:F70) -> 0 | G71: =SUM(G4:G70) -> 0 | H71: =SUM(H4:H70) -> 0 | I71: =SUM(I4:I70) -> 0 | J71: =SUM(J4:J70) -> 0 | K71: =SUM(K4:K70) -> 0 | ... BQ71: =SUM(BQ4:BQ70) -> 0 | BR71: =D71+F71+H71+J71+L71+N71+V71+X71+Z71+AB71+AD71+AF71+AZ71+BB71+BD71+BF71+BH71+AH71+P71+R71+AJ71+BJ71+AL71+AN71+AP71+AR71+AT71+AX71+AV71+BL71+T71 -> 0 | BS71: =E71+G71+I71+K71+M71+O71+W71+Y71+AA71+AC71+AE71+AG71+BA71+BC71+BE71+BG71+BI71+AI71+Q71+S71+AK71+BK71+AM71+AO71+AQ71+AS71+AU71+AY71 -> 0 | BT71: =SUM(BT4:BT70) -> 0 | BU71: =SUM(BU4:BU70) -> 0 | BV71: =BR71/BT71 -> #DIV/0! | BW71: =BR71/BS71 -> #DIV/0! | BX71: =BS71/BT71 -> #DIV/0!
BV72: =SUM(BV5:BV71) -> #DIV/0! | BW72: =SUM(BW5:BW71) -> #DIV/0! | BX72: =BR72/BU72 -> #DIV/0!
B74: No. Of Calls | C74: Line Code | D74: Pax Per Line | E74: Allotments | F74: Pax on Board | G74: Capture Rate | H74: Utilization Rate
A75: Royal | B75: =COUNTIF(B4:B70,"*RCL*") -> 0 | C75: RCL | D75: =SUMIF($B$4:$B$70,"RCL",BR4:BR70) -> 0 | E75: =SUMIF($B$4:$B$70,"RCL",BS4:BS70) -> 0 | F75: =SUMIF($B$4:$B$70,"RCL",BT4:BT70) -> 0 | G75: =IF(D75=0, "", D75/F75) | H75: =IF(D75=0, "",D75/E75) | I75: =IF(D75=0, "",D75/B75)
A76: Norwegian | B76: =COUNTIF(B4:B70,"*NCL*") -> 0 | C76: NCL | D76: =SUMIF($B$4:$B$70,"NCL",BR4:BR70) -> 0 | E76: =SUMIF($B$4:$B$70,"NCL",BS4:BS70) -> 0 | F76: =SUMIF($B$4:$B$70,"NCL",BT4:BT70) -> 0 | G76: =IF(D76=0, "", D76/F76) | H76: =IF(D76=0, "",D76/E76)
A77: Disney | B77: =COUNTIF(B4:B70,"*DCL*") -> 0 | C77: DCL | D77: =SUMIF($B$4:$B$70,"DCL",BR4:BR70) -> 0 | E77: =SUMIF($B$4:$B$70,"DCL",BS4:BS70) -> 0 | F77: =SUMIF($B$4:$B$70,"DCL",BT4:BT70) -> 0 | G77: =IF(D77=0, "", D77/F77) | H77: =IF(D77=0, "",D77/E77)
A78: Celebrity | B78: =COUNTIF(B4:B70,"*CEL*") -> 0 | C78: CEL | D78: =SUMIF($B$4:$B$70,"CEL",BR4:BR70) -> 0 | E78: =SUMIF($B$4:$B$70,"CEL",BS4:BS70) -> 0 | F78: =SUMIF($B$4:$B$70,"CEL",BT4:BT70) -> 0 | G78: =IF(D78=0, "", D78/F78) | H78: =IF(D78=0, "",D78/E78)
A79: Carnival | B79: =COUNTIF(B4:B70,"*CCL*") -> 0 | C79: CCL | D79: =SUMIF($B$4:$B$70,"CCL",BR4:BR70) -> 0 | E79: =SUMIF($B$4:$B$70,"CCL",BS4:BS70) -> 0 | F79: =SUMIF($B$4:$B$70,"CCL",BT4:BT70) -> 0 | G79: =IF(D79=0, "", D79/F79) | H79: =IF(D79=0, "",D79/E79)
A80: Princess | B80: =COUNTIF(B4:B70,"*PCL*") -> 0 | C80: PCL | D80: =SUMIF($B$4:$B$70,"PCL",BR4:BR70) -> 0 | E80: =SUMIF($B$4:$B$70,"PCL",BS4:BS70) -> 0 | F80: =SUMIF($B$4:$B$70,"PCL",BT4:BT70) -> 0 | G80: =IF(D80=0, "", D80/F80) | H80: =IF(D80=0, "",D80/E80)
A81: Holland | B81: =COUNTIF(B4:B70,"*HAL*") -> 0 | C81: HAL | D81: =SUMIF($B$4:$B$70,"HAL",BR4:BR70) -> 0 | E81: =SUMIF($B$4:$B$70,"HAL",BS4:BS70) -> 0 | F81: =SUMIF($B$4:$B$70,"HAL",BT4:BT70) -> 0 | G81: =IF(D81=0, "", D81/F81) | H81: =IF(D81=0, "",D81/E81)
A82: Silverseas | B82: =COUNTIF(B4:B70,"*Silver*") -> 0 | C82: Silver | D82: =SUMIF($B$4:$B$70,"Silver",BR4:BR70) -> 0 | E82: =SUMIF($B$4:$B$70,"Silver",BS4:BS70) -> 0 | F82: =SUMIF($B$4:$B$70,"Silver",BT4:BT70) -> 0 | G82: =IF(D82=0, "", D82/F82) | H82: =IF(D82=0, "",D82/E82)
A83: Viking | B83: =COUNTIF(B4:B70,"*Viking*") -> 0 | C83: Viking | D83: =SUMIF($B$4:$B$70,"Viking",BR4:BR70) -> 0 | E83: =SUMIF($B$4:$B$70,"Viking",BS4:BS70) -> 0 | F83: =SUMIF($B$4:$B$70,"Viking",BT4:BT70) -> 0 | G83: =IF(D83=0, "", D83/F83) | H83: =IF(D83=0, "",D83/E83)
A84: Azamara | B84: =COUNTIF(B4:B70,"*Azamara*") -> 0 | C84: Azamara | D84: =SUMIF($B$4:$B$70,"Azamara",BR4:BR70) -> 0 | E84: =SUMIF($B$4:$B$70,"Azamara",BS4:BS70) -> 0 | F84: =SUMIF($B$4:$B$70,"Azamara",BT4:BT70) -> 0 | G84: =IF(D84=0, "", D84/F84) | H84: =IF(D84=0, "",D84/E84)
A85: TUI | B85: =COUNTIF(B4:B70,"*TUI*") -> 0 | C85: TUI | D85: =SUMIF($B$4:$B$70,"TUI",BR4:BR70) -> 0 | E85: =SUMIF($B$4:$B$70,"TUI",BS4:BS70) -> 0 | F85: =SUMIF($B$4:$B$70,"TUI",BT4:BT70) -> 0 | G85: =IF(D85=0, "", D85/F85) | H85: =IF(D85=0, "",D85/E85)
A86: Marella | B86: =COUNTIF(B4:B70,"*Marella*") -> 0 | C86: Marella | D86: =SUMIF($B$4:$B$70,"Marella",BR4:BR70) -> 0 | E86: =SUMIF($B$4:$B$70,"Marella",BS4:BS70) -> 0 | F86: =SUMIF($B$4:$B$70,"Marella",BT4:BT70) -> 0 | G86: =IF(D86=0, "", D86/F86) | H86: =IF(D86=0, "",D86/E86)
A87: MSC | B87: =COUNTIF(B4:B70,"*MSC*") -> 0 | C87: MSC | D87: =SUMIF($B$4:$B$70,"MSC",BR4:BR70) -> 0 | E87: =SUMIF($B$4:$B$70,"MSC",BS4:BS70) -> 0 | F87: =SUMIF($B$4:$B$70,"MSC",BT4:BT70) -> 0 | G87: =IF(D87=0, "", D87/F87) | H87: =IF(D87=0, "",D87/E87)
A88: Regent | B88: =COUNTIF(B4:B70,"*Regent*") -> 0 | C88: Regent | D88: =SUMIF($B$4:$B$70,"Regent",BR4:BR70) -> 0 | E88: =SUMIF($B$4:$B$70,"Regent",BS4:BS70) -> 0 | F88: =SUMIF($B$4:$B$70,"Regent",BT4:BT70) -> 0 | G88: =IF(D88=0, "", D88/F88) | H88: =IF(D88=0, "",D88/E88)
A89: Windstar | B89: =COUNTIF(B5:B71,"*Windstar*") -> 0 | C89: Windstar | D89: =SUMIF($B$4:$B$70,"Windstar",BR4:BR70) -> 0 | E89: =SUMIF($B$4:$B$70,"Windstar",BS4:BS70) -> 0 | F89: =SUMIF($B$4:$B$70,"Windstar",BT4:BT70) -> 0 | G89: =IF(D89=0, "", D89/F89) | H89: =IF(D89=0, "",D89/E89)
A90: Explora | B90: =COUNTIF(B6:B72,"*Explora*") -> 0 | C90: Explora | D90: =SUMIF($B$4:$B$70,"Explora",BR4:BR70) -> 0 | E90: =SUMIF($B$4:$B$70,"Explora",BS4:BS70) -> 0 | F90: =SUMIF($B$4:$B$70,"Explora",BT4:BT70) -> 0 | G90: =IF(D90=0, "", D90/F90) | H90: =IF(D90=0, "",D90/E90)
A91: Cunard | B91: =COUNTIF(B7:B73,"*Cunard*") -> 0 | C91: Cunard | D91: =SUMIF($B$4:$B$70,"Cunard",BR4:BR70) -> 0 | E91: =SUMIF($B$4:$B$70,"Cunard",BS4:BS70) -> 0 | F91: =SUMIF($B$4:$B$70,"Cunard",BT4:BT70) -> 0 | G91: =IF(D91=0, "", D91/F91) | H91: =IF(D91=0, "",D91/E91)
B94: No. Of Calls | D94: Pax Per Line | E94: Allotments | F94: Pax on Board | G94: Capture Rate | H94: Utilization Rate
A95: Vista | B95: =COUNTIF(C4:C70,"*Vista*") -> 0 | D95: =SUMIF($C$4:$C$70,"Vista",$BR$4:$BR$70) -> 0 | E95: =SUMIF($C$4:$C$70,"Vista",$BS$4:$BS$70) -> 0 | F95: =SUMIF($C$4:$C$70,"Vista",$BT$4:$BT$70) -> 0 | G95: =IF(D95=0, "", D95/F95) | H95: =IF(D95=0, "",D95/E95) | I95: =IF(D95=0, "",D95/B95)
A96: Conquest | B96: =COUNTIF(C4:C70,"*Conquest*") -> 0 | D96: =SUMIF($C$4:$C$70,"Conquest",$BR$4:$BR$70) -> 0 | E96: =SUMIF($C$4:$C$70,"Conquest",$BS$4:$BS$70) -> 0 | F96: =SUMIF($C$4:$C$70,"Conquest",$BT$4:$BT$70) -> 0 | G96: =IF(D96=0, "", D96/F96) | H96: =IF(D96=0, "",D96/E96) | I96: =IF(D96=0, "",D96/B96)
A97: Glory | B97: =COUNTIF(C4:C70,"*Glory*") -> 0 | D97: =SUMIF($C$4:$C$70,"Glory",$BR$4:$BR$70) -> 0 | E97: =SUMIF($C$4:$C$70,"Glory",$BS$4:$BS$70) -> 0 | F97: =SUMIF($C$4:$C$70,"Glory",$BT$4:$BT$70) -> 0 | G97: =IF(D97=0, "", D97/F97) | H97: =IF(D97=0, "",D97/E97) | I97: =IF(D97=0, "",D97/B97)
...

Sheet Jan 26
A2: DATE | B2: LINE | C2: SHIP NAME | D2: Catamaran Sail & Snorkel | F2: Champagne Adults Only | H2: Invisible Boat Family | BR2: PAX TOTALS, ANALYSIS and RATES
D3: Sold | E3: Allotment | F3: Sold | G3: Allotment | H3: Sold | I3: Allotment | J3: Sold | K3: Allotment | L3: Sold | M3: Allotment | N3: Sold | O3: Allotment | P3: Sold | Q3: Allotment | R3: Sold | S3: Allotment | T3: Sold | U3: Allotment | V3: Sold | W3: Allotment | X3: Sold | Y3: Allotment | Z3: Sold | AA3: Allotment | AB3: Sold | AC3: Allotment | AD3: Sold | AE3: Allotment | AF3: Sold | AG3: Allotment | AH3: Sold | AI3: Allotment | AJ3: Sold | AK3: Allotment | AL3: Sold | AM3: Allotment | AN3: Sold | AO3: Allotment | AP3: Sold | AQ3: Allotment | AR3: Sold | AS3: Allotment | AT3: Sold | AU3: Allotment | AV3: Sold | AW3: Allotment | AX3: Sold | AY3: Allotment | AZ3: Sold | BA3: Allotment | BB3: Sold | BC3: Allotment | BD3: Sold | BE3: Allotment | BF3: Sold | BG3: Allotment | BH3: Sold | BI3: Allotment | BJ3: Sold | BK3: Allotment | BL3: Sold | BM3: Allotment | BN3: Sold | BO3: Allotment | BP3: Sold | BQ3: Allotment | BR3: Chukka Tours (Sold) | BS3: Alloted Pax | BT3: Pax on Board | BU3: Pax on Tour | BV3: Capture Rate | BW3: Utilization Rate | BX3: Market Share
A4: {{date}} | B4: {{cruise_line}} | C4: {{ship_name}} | D4: {{cat_sold}} | E4: {{cat_allot}} | F4: {{champ_sold}} | G4: {{champ_allot}} | H4: {{inv_sold}} | I4: {{inv_allot}} | BR4: =D4+F4+H4+J4+L4+N4+V4+X4+Z4+AB4+AD4+AF4+AZ4+BB4+BD4+BF4+BH4+AH4+P4+R4+AJ4+BJ4+AL4+AN4+AP4+AR4+AT4+AX4+AV4+BL4+T4+BN4+BP4 -> #VALUE! | BS4: =E4+G4+I4+K4+M4+O4+W4+Y4+AA4+AC4+AE4+AG4+BA4+BC4+BE4+BG4+BI4+AI4+Q4+S4+AK4+BK4+AM4+AO4+AQ4+AS4+AU4+AY4+AW4+BM4+U4+BO4+BQ4 -> #VALUE! | BT4: {{pax_on_board}} | BU4: {{pax_on_tour}} | BV4: =IF(BR4=0, "", BR4/BT4) -> #VALUE! | BW4: =IF(BR4=0, "", BR4/BS4) -> #VALUE! | BX4: =IF(BR4=0, "", BR4/BU4) -> #VALUE!
BR5: =D5+F5+H5+J5+L5+N5+V5+X5+Z5+AB5+AD5+AF5+AZ5+BB5+BD5+BF5+BH5+AH5+P5+R5+AJ5+BJ5+AL5+AN5+AP5+AR5+AT5+AX5+AV5+BL5+T5+BN5+BP5 -> 0 | BS5: =E5+G5+I5+K5+M5+O5+W5+Y5+AA5+AC5+AE5+AG5+BA5+BC5+BE5+BG5+BI5+AI5+Q5+S5+AK5+BK5+AM5+AO5+AQ5+AS5+AU5+AY5+AW5+BM5+U5+BO5+BQ5 -> 0 | BV5: =IF(BR5=0, "", BR5/BT5) | BW5: =IF(BR5=0, "", BR5/BS5) | BX5: =IF(BR5=0, "", BR5/BU5)
BR6: =D6+F6+H6+J6+L6+N6+V6+X6+Z6+AB6+AD6+AF6+AZ6+BB6+BD6+BF6+BH6+AH6+P6+R6+AJ6+BJ6+AL6+AN6+AP6+AR6+AT6+AX6+AV6+BL6+T6+BN6+BP6 -> 0 | BS6: =E6+G6+I6+K6+M6+O6+W6+Y6+AA6+AC6+AE6+AG6+BA6+BC6+BE6+BG6+BI6+AI6+Q6+S6+AK6+BK6+AM6+AO6+AQ6+AS6+AU6+AY6+AW6+BM6+U6+BO6+BQ6 -> 0 | BV6: =IF(BR6=0, "", BR6/BT6) | BW6: =IF(BR6=0, "", BR6/BS6) | BX6: =IF(BR6=0, "", BR6/BU6)
BR7: =D7+F7+H7+J7+L7+N7+V7+X7+Z7+AB7+AD7+AF7+AZ7+BB7+BD7+BF7+BH7+AH7+P7+R7+AJ7+BJ7+AL7+AN7+AP7+AR7+AT7+AX7+AV7+BL7+T7+BN7+BP7 -> 0 | BS7: =E7+G7+I7+K7+M7+O7+W7+Y7+AA7+AC7+AE7+AG7+BA7+BC7+BE7+BG7+BI7+AI7+Q7+S7+AK7+BK7+AM7+AO7+AQ7+AS7+AU7+AY7+AW7+BM7+U7+BO7+BQ7 -> 0 | BV7: =IF(BR7=0, "", BR7/BT7) | BW7: =IF(BR7=0, "", BR7/BS7) | BX7: =IF(BR7=0, "", BR7/BU7)
BR8: =D8+F8+H8+J8+L8+N8+V8+X8+Z8+AB8+AD8+AF8+AZ8+BB8+BD8+BF8+BH8+AH8+P8+R8+AJ8+BJ8+AL8+AN8+AP8+AR8+AT8+AX8+AV8+BL8+T8+BN8+BP8 -> 0 | BS8: =E8+G8+I8+K8+M8+O8+W8+Y8+AA8+AC8+AE8+AG8+BA8+BC8+BE8+BG8+BI8+AI8+Q8+S8+AK8+BK8+AM8+AO8+AQ8+AS8+AU8+AY8+AW8+BM8+U8+BO8+BQ8 -> 0 | BV8: =IF(BR8=0, "", BR8/BT8) | BW8: =IF(BR8=0, "", BR8/BS8) | BX8: =IF(BR8=0, "", BR8/BU8)
BR9: =D9+F9+H9+J9+L9+N9+V9+X9+Z9+AB9+AD9+AF9+AZ9+BB9+BD9+BF9+BH9+AH9+P9+R9+AJ9+BJ9+AL9+AN9+AP9+AR9+AT9+AX9+AV9+BL9+T9+BN9+BP9 -> 0 | BS9: =E9+G9+I9+K9+M9+O9+W9+Y9+AA9+AC9+AE9+AG9+BA9+BC9+BE9+BG9+BI9+AI9+Q9+S9+AK9+BK9+AM9+AO9+AQ9+AS9+AU9+AY9+AW9+BM9+U9+BO9+BQ9 -> 0 | BV9: =IF(BR9=0, "", BR9/BT9) | BW9: =IF(BR9=0, "", BR9/BS9) | BX9: =IF(BR9=0, "", BR9/BU9)
BR10: =D10+F10+H10+J10+L10+N10+V10+X10+Z10+AB10+AD10+AF10+AZ10+BB10+BD10+BF10+BH10+AH10+P10+R10+AJ10+BJ10+AL10+AN10+AP10+AR10+AT10+AX10+AV10+BL10+T10+BN10+BP10 -> 0 | BS10: =E10+G10+I10+K10+M10+O10+W10+Y10+AA10+AC10+AE10+AG10+BA10+BC10+BE10+BG10+BI10+AI10+Q10+S10+AK10+BK10+AM10+AO10+AQ10+AS10+AU10+AY10+AW10+BM10+U10+BO10+BQ10 -> 0 | BV10: =IF(BR10=0, "", BR10/BT10) | BW10: =IF(BR10=0, "", BR10/BS10) | BX10: =IF(BR10=0, "", BR10/BU10)
BR11: =D11+F11+H11+J11+L11+N11+V11+X11+Z11+AB11+AD11+AF11+AZ11+BB11+BD11+BF11+BH11+AH11+P11+R11+AJ11+BJ11+AL11+AN11+AP11+AR11+AT11+AX11+AV11+BL11+T11+BN11+BP11 -> 0 | BS11: =E11+G11+I11+K11+M11+O11+W11+Y11+AA11+AC11+AE11+AG11+BA11+BC11+BE11+BG11+BI11+AI11+Q11+S11+AK11+BK11+AM11+AO11+AQ11+AS11+AU11+AY11+AW11+BM11+U11+BO11+BQ11 -> 0 | BV11: =IF(BR11=0, "", BR11/BT11) | BW11: =IF(BR11=0, "", BR11/BS11) | BX11: =IF(BR11=0, "", BR11/BU11)
BR12: =D12+F12+H12+J12+L12+N12+V12+X12+Z12+AB12+AD12+AF12+AZ12+BB12+BD12+BF12+BH12+AH12+P12+R12+AJ12+BJ12+AL12+AN12+AP12+AR12+AT12+AX12+AV12+BL12+T12+BN12+BP12 -> 0 | BS12: =E12+G12+I12+K12+M12+O12+W12+Y12+AA12+AC12+AE12+AG12+BA12+BC12+BE12+BG12+BI12+AI12+Q12+S12+AK12+BK12+AM12+AO12+AQ12+AS12+AU12+AY12+AW12+BM12+U12+BO12+BQ12 -> 0 | BV12: =IF(BR12=0, "", BR12/BT12) | BW12: =IF(BR12=0, "", BR12/BS12) | BX12: =IF(BR12=0, "", BR12/BU12)
BR13: =D13+F13+H13+J13+L13+N13+V13+X13+Z13+AB13+AD13+AF13+AZ13+BB13+BD13+BF13+BH13+AH13+P13+R13+AJ13+BJ13+AL13+AN13+AP13+AR13+AT13+AX13+AV13+BL13+T13+BN13+BP13 -> 0 | BS13: =E13+G13+I13+K13+M13+O13+W13+Y13+AA13+AC13+AE13+AG13+BA13+BC13+BE13+BG13+BI13+AI13+Q13+S13+AK13+BK13+AM13+AO13+AQ13+AS13+AU13+AY13+AW13+BM13+U13+BO13+BQ13 -> 0 | BV13: =IF(BR13=0, "", BR13/BT13) | BW13: =IF(BR13=0, "", BR13/BS13) | BX13: =IF(BR13=0, "", BR13/BU13)
BR14: =D14+F14+H14+J14+L14+N14+V14+X14+Z14+AB14+AD14+AF14+AZ14+BB14+BD14+BF14+BH14+AH14+P14+R14+AJ14+BJ14+AL14+AN14+AP14+AR14+AT14+AX14+AV14+BL14+T14+BN14+BP14 -> 0 | BS14: =E14+G14+I14+K14+M14+O14+W14+Y14+AA14+AC14+AE14+AG14+BA14+BC14+BE14+BG14+BI14+AI14+Q14+S14+AK14+BK14+AM14+AO14+AQ14+AS14+AU14+AY14+AW14+BM14+U14+BO14+BQ14 -> 0 | BV14: =IF(BR14=0, "", BR14/BT14) | BW14: =IF(BR14=0, "", BR14/BS14) | BX14: =IF(BR14=0, "", BR14/BU14)
BR15: =D15+F15+H15+J15+L15+N15+V15+X15+Z15+AB15+AD15+AF15+AZ15+BB15+BD15+BF15+BH15+AH15+P15+R15+AJ15+BJ15+AL15+AN15+AP15+AR15+AT15+AX15+AV15+BL15+T15+BN15+BP15 -> 0 | BS15: =E15+G15+I15+K15+M15+O15+W15+Y15+AA15+AC15+AE15+AG15+BA15+BC15+BE15+BG15+BI15+AI15+Q15+S15+AK15+BK15+AM15+AO15+AQ15+AS15+AU15+AY15+AW15+BM15+U15+BO15+BQ15 -> 0 | BV15: =IF(BR15=0, "", BR15/BT15) | BW15: =IF(BR15=0, "", BR15/BS15) | BX15: =IF(BR15=0, "", BR15/BU15)
BR16: =D16+F16+H16+J16+L16+N16+V16+X16+Z16+AB16+AD16+AF16+AZ16+BB16+BD16+BF16+BH16+AH16+P16+R16+AJ16+BJ16+AL16+AN16+AP16+AR16+AT16+AX16+AV16+BL16+T16+BN16+BP16 -> 0 | BS16: =E16+G16+I16+K16+M16+O16+W16+Y16+AA16+AC16+AE16+AG16+BA16+BC16+BE16+BG16+BI16+AI16+Q16+S16+AK16+BK16+AM16+AO16+AQ16+AS16+AU16+AY16+AW16+BM16+U16+BO16+BQ16 -> 0 | BV16: =IF(BR16=0, "", BR16/BT16) | BW16: =IF(BR16=0, "", BR16/BS16) | BX16: =IF(BR16=0, "", BR16/BU16)
... BR70: =D70+F70+H70+J70+L70+N70+V70+X70+Z70+AB70+AD70+AF70+AZ70+BB70+BD70+BF70+BH70+AH70+P70+R70+AJ70+BJ70+AL70+AN70+AP70+AR70+AT70+AX70+AV70+BL70+T70+BN70+BP70 -> 0 | BS70: =E70+G70+I70+K70+M70+O70+W70+Y70+AA70+AC70+AE70+AG70+BA70+BC70+BE70+BG70+BI70+AI70+Q70+S70+AK70+BK70+AM70+AO70+AQ70+AS70+AU70+AY70+AW70+BM70+U70+BO70+BQ70 -> 0 | BV70: =IF(BR70=0, "", BR70/BT70) | BW70: =IF(BR70=0, "", BR70/BS70) | BX70: =IF(BR70=0, "", BR70/BU70)
B71: TOTAL | D71: =SUM(D4:D70) -> 0 | E71: =SUM(E4:E70) -> 0 | F71: =SUM(F4:F70) -> 0 | G71: =SUM(G4:G70) -> 0 | H71: =SUM(H4:H70) -> 0 | I71: =SUM(I4:I70) -> 0 | J71: =SUM(J4:J70) -> 0 | K71: =SUM(K4:K70) -> 0 | ... BQ71: =SUM(BQ4:BQ70) -> 0 | BR71: =D71+F71+H71+J71+L71+N71+V71+X71+Z71+AB71+AD71+AF71+AZ71+BB71+BD71+BF71+BH71+AH71+P71+R71+AJ71+BJ71+AL71+AN71+AP71+AR71+AT71+AX71+AV71+BL71+T71 -> 0 | BS71: =E71+G71+I71+K71+M71+O71+W71+Y71+AA71+AC71+AE71+AG71+BA71+BC71+BE71+BG71+BI71+AI71+Q71+S71+AK71+BK71+AM71+AO71+AQ71+AS71+AU71+AY71 -> 0 | BT71: =SUM(BT4:BT70) -> 0 | BU71: =SUM(BU4:BU70) -> 0 | BV71: =BR71/BT71 -> #DIV/0! | BW71: =BR71/BS71 -> #DIV/0! | BX71: =BR71/BU71 -> #DIV/0!
B74: No. Of Calls | C74: Line Code | D74: Pax Per Line | E74: Allotments | F74: Pax on Board | G74: Capture Rate | H74: Utilization Rate
A75: Royal | B75: =COUNTIF(B4:B70,"*RCL*") -> 0 | C75: RCL | D75: =SUMIF($B$4:$B$70,"RCL",BR4:BR70) -> 0 | E75: =SUMIF($B$4:$B$70,"RCL",BS4:BS70) -> 0 | F75: =SUMIF($B$4:$B$70,"RCL",BT4:BT70) -> 0 | G75: =IF(D75=0, "", D75/F75) | H75: =IF(D75=0, "",D75/E75) | I75: =IF(D75=0, "",D75/B75)
A76: Norwegian | B76: =COUNTIF(B4:B70,"*NCL*") -> 0 | C76: NCL | D76: =SUMIF($B$4:$B$70,"NCL",BR4:BR70) -> 0 | E76: =SUMIF($B$4:$B$70,"NCL",BS4:BS70) -> 0 | F76: =SUMIF($B$4:$B$70,"NCL",BT4:BT70) -> 0 | G76: =IF(D76=0, "", D76/F76) | H76: =IF(D76=0, "",D76/E76)
A77: Disney | B77: =COUNTIF(B4:B70,"*DCL*") -> 0 | C77: DCL | D77: =SUMIF($B$4:$B$70,"DCL",BR4:BR70) -> 0 | E77: =SUMIF($B$4:$B$70,"DCL",BS4:BS70) -> 0 | F77: =SUMIF($B$4:$B$70,"DCL",BT4:BT70) -> 0 | G77: =IF(D77=0, "", D77/F77) | H77: =IF(D77=0, "",D77/E77)
A78: Celebrity | B78: =COUNTIF(B4:B70,"*CEL*") -> 0 | C78: CEL | D78: =SUMIF($B$4:$B$70,"CEL",BR4:BR70) -> 0 | E78: =SUMIF($B$4:$B$70,"CEL",BS4:BS70) -> 0 | F78: =SUMIF($B$4:$B$70,"CEL",BT4:BT70) -> 0 | G78: =IF(D78=0, "", D78/F78) | H78: =IF(D78=0, "",D78/E78)
A79: Carnival | B79: =COUNTIF(B4:B70,"*CCL*") -> 0 | C79: CCL | D79: =SUMIF($B$4:$B$70,"CCL",BR4:BR70) -> 0 | E79: =SUMIF($B$4:$B$70,"CCL",BS4:BS70) -> 0 | F79: =SUMIF($B$4:$B$70,"CCL",BT4:BT70) -> 0 | G79: =IF(D79=0, "", D79/F79) | H79: =IF(D79=0, "",D79/E79)
A80: Princess | B80: =COUNTIF(B4:B70,"*PCL*") -> 0 | C80: PCL | D80: =SUMIF($B$4:$B$70,"PCL",BR4:BR70) -> 0 | E80: =SUMIF($B$4:$B$70,"PCL",BS4:BS70) -> 0 | F80: =SUMIF($B$4:$B$70,"PCL",BT4:BT70) -> 0 | G80: =IF(D80=0, "", D80/F80) | H80: =IF(D80=0, "",D80/E80)
A81: Holland | B81: =COUNTIF(B4:B70,"*HAL*") -> 0 | C81: HAL | D81: =SUMIF($B$4:$B$70,"HAL",BR4:BR70) -> 0 | E81: =SUMIF($B$4:$B$70,"HAL",BS4:BS70) -> 0 | F81: =SUMIF($B$4:$B$70,"HAL",BT4:BT70) -> 0 | G81: =IF(D81=0, "", D81/F81) | H81: =IF(D81=0, "",D81/E81)
A82: Silverseas | B82: =COUNTIF(B4:B70,"*Silver*") -> 0 | C82: Silver | D82: =SUMIF($B$4:$B$70,"Silver",BR4:BR70) -> 0 | E82: =SUMIF($B$4:$B$70,"Silver",BS4:BS70) -> 0 | F82: =SUMIF($B$4:$B$70,"Silver",BT4:BT70) -> 0 | G82: =IF(D82=0, "", D82/F82) | H82: =IF(D82=0, "",D82/E82)
A83: Viking | B83: =COUNTIF(B4:B70,"*Viking*") -> 0 | C83: Viking | D83: =SUMIF($B$4:$B$70,"Viking",BR4:BR70) -> 0 | E83: =SUMIF($B$4:$B$70,"Viking",BS4:BS70) -> 0 | F83: =SUMIF($B$4:$B$70,"Viking",BT4:BT70) -> 0 | G83: =IF(D83=0, "", D83/F83) | H83: =IF(D83=0, "",D83/E83)
A84: Azamara | B84: =COUNTIF(B4:B70,"*Azamara*") -> 0 | C84: Azamara | D84: =SUMIF($B$4:$B$70,"Azamara",BR4:BR70) -> 0 | E84: =SUMIF($B$4:$B$70,"Azamara",BS4:BS70) -> 0 | F84: =SUMIF($B$4:$B$70,"Azamara",BT4:BT70) -> 0 | G84: =IF(D84=0, "", D84/F84) | H84: =IF(D84=0, "",D84/E84)
A85: TUI | B85: =COUNTIF(B4:B70,"*TUI*") -> 0 | C85: TUI | D85: =SUMIF($B$4:$B$70,"TUI",BR4:BR70) -> 0 | E85: =SUMIF($B$4:$B$70,"TUI",BS4:BS70) -> 0 | F85: =SUMIF($B$4:$B$70,"TUI",BT4:BT70) -> 0 | G85: =IF(D85=0, "", D85/F85) | H85: =IF(D85=0, "",D85/E85)
A86: Marella | B86: =COUNTIF(B4:B70,"*Marella*") -> 0 | C86: Marella | D86: =SUMIF($B$4:$B$70,"Marella",BR4:BR70) -> 0 | E86: =SUMIF($B$4:$B$70,"Marella",BS4:BS70) -> 0 | F86: =SUMIF($B$4:$B$70,"Marella",BT4:BT70) -> 0 | G86: =IF(D86=0, "", D86/F86) | H86: =IF(D86=0, "",D86/E86)
A87: MSC | B87: =COUNTIF(B4:B70,"*MSC*") -> 0 | C87: MSC | D87: =SUMIF($B$4:$B$70,"MSC",BR4:BR70) -> 0 | E87: =SUMIF($B$4:$B$70,"MSC",BS4:BS70) -> 0 | F87: =SUMIF($B$4:$B$70,"MSC",BT4:BT70) -> 0 | G87: =IF(D87=0, "", D87/F87) | H87: =IF(D87=0, "",D87/E87)
A88: Regent | B88: =COUNTIF(B4:B70,"*Regent*") -> 0 | C88: Regent | D88: =SUMIF($B$4:$B$70,"Regent",BR4:BR70) -> 0 | E88: =SUMIF($B$4:$B$70,"Regent",BS4:BS70) -> 0 | F88: =SUMIF($B$4:$B$70,"Regent",BT4:BT70) -> 0 | G88: =IF(D88=0, "", D88/F88) | H88: =IF(D88=0, "",D88/E88)
A89: Windstar | B89: =COUNTIF(B5:B71,"*Windstar*") -> 0 | C89: Windstar | D89: =SUMIF($B$4:$B$70,"Windstar",BR4:BR70) -> 0 | E89: =SUMIF($B$4:$B$70,"Windstar",BS4:BS70) -> 0 | F89: =SUMIF($B$4:$B$70,"Windstar",BT4:BT70) -> 0 | G89: =IF(D89=0, "", D89/F89) | H89: =IF(D89=0, "",D89/E89)
A90: Explora | B90: =COUNTIF(B6:B72,"*Explora*") -> 0 | C90: Explora | D90: =SUMIF($B$4:$B$70,"Explora",BR4:BR70) -> 0 | E90: =SUMIF($B$4:$B$70,"Explora",BS4:BS70) -> 0 | F90: =SUMIF($B$4:$B$70,"Explora",BT4:BT70) -> 0 | G90: =IF(D90=0, "", D90/F90) | H90: =IF(D90=0, "",D90/E90)
A91: Cunard | B91: =COUNTIF(B7:B73,"*Cunard*") -> 0 | C91: Cunard | D91: =SUMIF($B$4:$B$70,"Cunard",BR4:BR70) -> 0 | E91: =SUMIF($B$4:$B$70,"Cunard",BS4:BS70) -> 0 | F91: =SUMIF($B$4:$B$70,"Cunard",BT4:BT70) -> 0 | G91: =IF(D91=0, "", D91/F91) | H91: =IF(D91=0, "",D91/E91)
B93: =SUM(B75:B91) -> 0
B94: No. Of Calls | D94: Pax Per Line | E94: Allotments | F94: Pax on Board | G94: Capture Rate | H94: Utilization Rate
A95: Vista | B95: =COUNTIF(C4:C70,"*Vista*") -> 0 | D95: =SUMIF($C$4:$C$70,"Vista",$BR$4:$BR$70) -> 0 | E95: =SUMIF($C$4:$C$70,"Vista",$BS$4:$BS$70) -> 0 | F95: =SUMIF($C$4:$C$70,"Vista",$BT$4:$BT$70) -> 0 | G95: =IF(D95=0, "", D95/F95) | H95: =IF(D95=0, "",D95/E95) | I95: =IF(D95=0, "",D95/B95)
A96: Conquest | B96: =COUNTIF(C4:C70,"*Conquest*") -> 0 | D96: =SUMIF($C$4:$C$70,"Conquest",$BR$4:$BR$70) -> 0 | E96: =SUMIF($C$4:$C$70,"Conquest",$BS$4:$BS$70) -> 0 | F96: =SUMIF($C$4:$C$70,"Conquest",$BT$4:$BT$70) -> 0 | G96: =IF(D96=0, "", D96/F96) | H96: =IF(D96=0, "",D96/E96) | I96: =IF(D96=0, "",D96/B96)
A97: Glory | B97: =COUNTIF(C4:C70,"*Glory*") -> 0 | D97: =SUMIF($C$4:$C$70,"Glory",$BR$4:$BR$70) -> 0 | E97: =SUMIF($C$4:$C$70,"Glory",$BS$4:$BS$70) -> 0 | F97: =SUMIF($C$4:$C$70,"Glory",$BT$4:$BT$70) -> 0 | G97: =IF(D97=0, "", D97/F97) | H97: =IF(D97=0, "",D97/E97) | I97: =IF(D97=0, "",D97/B97)
...

Sheet Feb 26
A2: DATE | B2: LINE | C2: SHIP NAME | D2: Catamaran Sail & Snorkel | F2: Champagne Adults Only | H2: Invisible Boat Family | BR2: PAX TOTALS, ANALYSIS and RATES
D3: Sold | E3: Allotment | F3: Sold | G3: Allotment | H3: Sold | I3: Allotment | J3: Sold | K3: Allotment | L3: Sold | M3: Allotment | N3: Sold | O3: Allotment | P3: Sold | Q3: Allotment | R3: Sold | S3: Allotment | T3: Sold | U3: Allotment | V3: Sold | W3: Allotment | X3: Sold | Y3: Allotment | Z3: Sold | AA3: Allotment | AB3: Sold | AC3: Allotment | AD3: Sold | AE3: Allotment | AF3: Sold | AG3: Allotment | AH3: Sold | AI3: Allotment | AJ3: Sold | AK3: Allotment | AL3: Sold | AM3: Allotment | AN3: Sold | AO3: Allotment | AP3: Sold | AQ3: Allotment | AR3: Sold | AS3: Allotment | AT3: Sold | AU3: Allotment | AV3: Sold | AW3: Allotment | AX3: Sold | AY3: Allotment | AZ3: Sold | BA3: Allotment | BB3: Sold | BC3: Allotment | BD3: Sold | BE3: Allotment | BF3: Sold | BG3: Allotment | BH3: Sold | BI3: Allotment | BJ3: Sold | BK3: Allotment | BL3: Sold | BM3: Allotment | BN3: Sold | BO3: Allotment | BP3: Sold | BQ3: Allotment | BR3: Chukka Tours (Sold) | BS3: Alloted Pax | BT3: Pax on Board | BU3: Pax on Tour | BV3: Capture Rate | BW3: Utilization Rate | BX3: Market Share
A4: {{date}} | B4: {{cruise_line}} | C4: {{ship_name}} | D4: {{cat_sold}} | E4: {{cat_allot}} | F4: {{champ_sold}} | G4: {{champ_allot}} | H4: {{inv_sold}} | I4: {{inv_allot}} | BR4: =D4+F4+H4+J4+L4+N4+V4+X4+Z4+AB4+AD4+AF4+AZ4+BB4+BD4+BF4+BH4+AH4+P4+R4+AJ4+BJ4+AL4+AN4+AP4+AR4+AT4+AX4+AV4+BL4+T4+BN4+BP4 -> #VALUE! | BS4: =E4+G4+I4+K4+M4+O4+W4+Y4+AA4+AC4+AE4+AG4+BA4+BC4+BE4+BG4+BI4+AI4+Q4+S4+AK4+BK4+AM4+AO4+AQ4+AS4+AU4+AY4+AW4+BM4+U4+BO4+BQ4 -> #VALUE! | BT4: {{pax_on_board}} | BU4: {{pax_on_tour}} | BV4: =IF(BR4=0, "", BR4/BT4) -> #VALUE! | BW4: =IF(BR4=0, "", BR4/BS4) -> #VALUE! | BX4: =IF(BR4=0, "", BR4/BU4) -> #VALUE!
BR5: =D5+F5+H5+J5+L5+N5+V5+X5+Z5+AB5+AD5+AF5+AZ5+BB5+BD5+BF5+BH5+AH5+P5+R5+AJ5+BJ5+AL5+AN5+AP5+AR5+AT5+AX5+AV5+BL5+T5+BN5+BP5 -> 0 | BS5: =E5+G5+I5+K5+M5+O5+W5+Y5+AA5+AC5+AE5+AG5+BA5+BC5+BE5+BG5+BI5+AI5+Q5+S5+AK5+BK5+AM5+AO5+AQ5+AS5+AU5+AY5+AW5+BM5+U5+BO5+BQ5 -> 0 | BV5: =IF(BR5=0, "", BR5/BT5) | BW5: =IF(BR5=0, "", BR5/BS5) | BX5: =IF(BR5=0, "", BR5/BU5)
BR6: =D6+F6+H6+J6+L6+N6+V6+X6+Z6+AB6+AD6+AF6+AZ6+BB6+BD6+BF6+BH6+AH6+P6+R6+AJ6+BJ6+AL6+AN6+AP6+AR6+AT6+AX6+AV6+BL6+T6+BN6+BP6 -> 0 | BS6: =E6+G6+I6+K6+M6+O6+W6+Y6+AA6+AC6+AE6+AG6+BA6+BC6+BE6+BG6+BI6+AI6+Q6+S6+AK6+BK6+AM6+AO6+AQ6+AS6+AU6+AY6+AW6+BM6+U6+BO6+BQ6 -> 0 | BV6: =IF(BR6=0, "", BR6/BT6) | BW6: =IF(BR6=0, "", BR6/BS6) | BX6: =IF(BR6=0, "", BR6/BU6)
BR7: =D7+F7+H7+J7+L7+N7+V7+X7+Z7+AB7+AD7+AF7+AZ7+BB7+BD7+BF7+BH7+AH7+P7+R7+AJ7+BJ7+AL7+AN7+AP7+AR7+AT7+AX7+AV7+BL7+T7+BN7+BP7 -> 0 | BS7: =E7+G7+I7+K7+M7+O7+W7+Y7+AA7+AC7+AE7+AG7+BA7+BC7+BE7+BG7+BI7+AI7+Q7+S7+AK7+BK7+AM7+AO7+AQ7+AS7+AU7+AY7+AW7+BM7+U7+BO7+BQ7 -> 0 | BV7: =IF(BR7=0, "", BR7/BT7) | BW7: =IF(BR7=0, "", BR7/BS7) | BX7: =IF(BR7=0, "", BR7/BU7)
BR8: =D8+F8+H8+J8+L8+N8+V8+X8+Z8+AB8+AD8+AF8+AZ8+BB8+BD8+BF8+BH8+AH8+P8+R8+AJ8+BJ8+AL8+AN8+AP8+AR8+AT8+AX8+AV8+BL8+T8+BN8+BP8 -> 0 | BS8: =E8+G8+I8+K8+M8+O8+W8+Y8+AA8+AC8+AE8+AG8+BA8+BC8+BE8+BG8+BI8+AI8+Q8+S8+AK8+BK8+AM8+AO8+AQ8+AS8+AU8+AY8+AW8+BM8+U8+BO8+BQ8 -> 0 | BV8: =IF(BR8=0, "", BR8/BT8) | BW8: =IF(BR8=0, "", BR8/BS8) | BX8: =IF(BR8=0, "", BR8/BU8)
BR9: =D9+F9+H9+J9+L9+N9+V9+X9+Z9+AB9+AD9+AF9+AZ9+BB9+BD9+BF9+BH9+AH9+P9+R9+AJ9+BJ9+AL9+AN9+AP9+AR9+AT9+AX9+AV9+BL9+T9+BN9+BP9 -> 0 | BS9: =E9+G9+I9+K9+M9+O9+W9+Y9+AA9+AC9+AE9+AG9+BA9+BC9+BE9+BG9+BI9+AI9+Q9+S9+AK9+BK9+AM9+AO9+AQ9+AS9+AU9+AY9+AW9+BM9+U9+BO9+BQ9 -> 0 | BV9: =IF(BR9=0, "", BR9/BT9) | BW9: =IF(BR9=0, "", BR9/BS9) | BX9: =IF(BR9=0, "", BR9/BU9)
BR10: =D10+F10+H10+J10+L10+N10+V10+X10+Z10+AB10+AD10+AF10+AZ10+BB10+BD10+BF10+BH10+AH10+P10+R10+AJ10+BJ10+AL10+AN10+AP10+AR10+AT10+AX10+AV10+BL10+T10+BN10+BP10 -> 0 | BS10: =E10+G10+I10+K10+M10+O10+W10+Y10+AA10+AC10+AE10+AG10+BA10+BC10+BE10+BG10+BI10+AI10+Q10+S10+AK10+BK10+AM10+AO10+AQ10+AS10+AU10+AY10+AW10+BM10+U10+BO10+BQ10 -> 0 | BV10: =IF(BR10=0, "", BR10/BT10) | BW10: =IF(BR10=0, "", BR10/BS10) | BX10: =IF(BR10=0, "", BR10/BU10)
BR11: =D11+F11+H11+J11+L11+N11+V11+X11+Z11+AB11+AD11+AF11+AZ11+BB11+BD11+BF11+BH11+AH11+P11+R11+AJ11+BJ11+AL11+AN11+AP11+AR11+AT11+AX11+AV11+BL11+T11+BN11+BP11 -> 0 | BS11: =E11+G11+I11+K11+M11+O11+W11+Y11+AA11+AC11+AE11+AG11+BA11+BC11+BE11+BG11+BI11+AI11+Q11+S11+AK11+BK11+AM11+AO11+AQ11+AS11+AU11+AY11+AW11+BM11+U11+BO11+BQ11 -> 0 | BV11: =IF(BR11=0, "", BR11/BT11) | BW11: =IF(BR11=0, "", BR11/BS11) | BX11: =IF(BR11=0, "", BR11/BU11)
